Workbook

Sheet DASHBOARD
B3: TAHUN | D3: Penjualan | E3: Barang Keluar | G3: Pembelian | H3: Barang Masuk | J3: Laba Kotor | K3: Pengeluaran Tercatat | L3: Laba Bersih
B4: 2026 | D4: =SUMIFS('SELLING CASH'!$I:$I, 'SELLING CASH'!$C:$C, ">=" & DATE($B$4, 1, 1), 'SELLING CASH'!$C:$C, "<=" & DATE($B$4, 12, 31), 'SELLING CASH'!$R:$R, "<>OIL") + SUMIFS('SELLING CREDIT'!$P:$P, 'SELLING CREDIT'!$C:$C, ">=" & DATE($B$4, 1, 1), 'SELLING CREDIT'!$C:$C, "<=" & DATE($B$4, 12, 31), 'SELLING CREDIT'!$S:$S, "<>OIL") -> 3771168000 | E4: =SUMIFS('SELLING CASH'!$F:$F, 'SELLING CASH'!$C:$C, ">=" & DATE($B$4, 1, 1), 'SELLING CASH'!$C:$C, "<=" & DATE($B$4, 12, 31), 'SELLING CASH'!$R:$R, "TIRE") + SUMIFS('SELLING CREDIT'!$G:$G, 'SELLING CREDIT'!$C:$C, ">=" & DATE($B$4, 1, 1), 'SELLING CREDIT'!$C:$C, "<=" & DATE($B$4, 12, 31), 'SELLING CREDIT'!$S:$S, "TIRE") -> 4341 | G4: =SUMIFS(PURCHASE!$N:$N, PURCHASE!$C:$C, ">=" & DATE($B$4, 1, 1), PURCHASE!$C:$C, "<=" & DATE($B$4, 12, 31), PURCHASE!$P:$P, "TIRE") -> 2908967163 | H4: =SUMIFS(PURCHASE!$J:$J, PURCHASE!$C:$C, ">=" & DATE($B$4, 1, 1), PURCHASE!$C:$C, "<=" & DATE($B$4, 12, 31), PURCHASE!$P:$P, "TIRE") -> 3875 | J4: =SUMIFS('SELLING CASH'!$N:$N, 'SELLING CASH'!$C:$C, ">=" & DATE($B$4, 1, 1), 'SELLING CASH'!$C:$C, "<=" & DATE($B$4, 12, 31), 'SELLING CASH'!$R:$R, "<>OIL", 'SELLING CASH'!$R:$R, "<>SERVICE") + SUMIFS('PAYMENT CREDIT'!$G:$G, 'PAYMENT CREDIT'!$C:$C, ">=" & DATE($B$4, 1, 1), 'PAYMENT CREDIT'!$C:$C, "<=" & DATE($B$4, 12, 31)) -> 447263000 | K4: =SUMIFS(EXPENSES!$D:$D, EXPENSES!$C:$C, ">=" & DATE($B$4, 1, 1), EXPENSES!$C:$C, "<=" & DATE($B$4, 12, 31)) -> 435942091 | L4: =J4-K4 -> 11320909

Sheet DAILY REPORT
A1: -
A2: 27375 | E2: 46290 | L2: Month | M2: September
A3: 22500 | P3: =SUM(P6:P36) -> 3810000 | Q3: GRAND TOTAL | S3: =SUM(S6:S40) -> 290510000 | T3: =SUM(T6:T40) -> 38538000 | U3: =SUM(U6:U40) -> 10160000 | V3: =SUM(V6:V40) -> 339208000 | W3: =SUM(W6:W40) -> 12645000 | Y3: BIAN
A4: 0 | L4: Tanggal | M4: CASH | Q4: TEMPO | S4: Jumlah | V4: TOTAL | W4: oil | Y4: =sum(Y7:Y37) -> 2075000 | Z4: =sum(Z7:Z37) -> 1480000
D5: Report | E5: =E2 -> 46290 | G5: Detail | M5: Modal | N5: Laba | O5: Spooring | P5: Service fee | Q5: Modal | R5: Laba | S5: Modal | T5: Laba | U5: Spooring | Y5: Modal | Z5: Laba
D6: Revenue | E6: =sumifs('SELLING CASH'!I:I,'SELLING CASH'!C:C,E5,'SELLING CASH'!R:R,"<>OIL") -> 15025000 | G6: Toko | H6: =E15-(H7+H8) -> 7623000 | L6: 46266 | M6: =sumifs('SELLING CASH'!I:I,'SELLING CASH'!C:C,L6,'SELLING CASH'!R:R,"<>OIL")-(N6+O6+P6) -> 12555000 | N6: =sumifs('SELLING CASH'!N:N,'SELLING CASH'!C:C,L6,'SELLING CASH'!R:R,"<>SERVICE",'SELLING CASH'!R:R, "<>OIL") -> 1445000 | O6: =sumifs('SELLING CASH'!N:N,'SELLING CASH'!C:C,L6,'SELLING CASH'!R:R,"SERVICE") -> 490000 | P6: =sumif('SELLING CASH'!C:C,L6,'SELLING CASH'!J:J) -> 95000 | Q6: =SUMIF('PAYMENT CREDIT'!C:C,L6,'PAYMENT CREDIT'!F:F)-R6 -> 4400000 | R6: =SUMIF('PAYMENT CREDIT'!C:C,L6,'PAYMENT CREDIT'!G:G) -> 600000 | S6: =M6+Q6 -> 16955000 | T6: =N6+R6 -> 2045000 | U6: =O6 -> 490000 | V6: =SUM(S6:U6) -> 19490000 | W6: =SUMIFS('SELLING CASH'!I:I,'SELLING CASH'!C:C,L6,'SELLING CASH'!R:R,"OIL") -> 885000
D7: Receivable Revenue | E7: =sumif('PAYMENT CREDIT'!C:C,E5,'PAYMENT CREDIT'!F:F) -> 0 | G7: Profit | H7: =SUMIFS('SELLING CASH'!N:N, 'SELLING CASH'!C:C, E5, 'SELLING CASH'!R:R, "<>SERVICE", 'SELLING CASH'!R:R, "<>OIL") + SUMIF('PAYMENT CREDIT'!C:C, E5, 'PAYMENT CREDIT'!G:G)- E10-E14-SUMIF('SELLING CREDIT'!C:C,E5,'SELLING CREDIT'!K:K) -> 1380000 | L7: 46267 | M7: =sumifs('SELLING CASH'!I:I,'SELLING CASH'!C:C,L7,'SELLING CASH'!R:R,"<>OIL")-(N7+O7+P7) -> 7760000 | N7: =sumifs('SELLING CASH'!N:N,'SELLING CASH'!C:C,L7,'SELLING CASH'!R:R,"<>SERVICE",'SELLING CASH'!R:R, "<>OIL") -> 1365000 | O7: =sumifs('SELLING CASH'!N:N,'SELLING CASH'!C:C,L7,'SELLING CASH'!R:R,"SERVICE") -> 355000 | P7: =sumif('SELLING CASH'!C:C,L7,'SELLING CASH'!J:J) -> 95000 | Q7: =SUMIF('PAYMENT CREDIT'!C:C,L7,'PAYMENT CREDIT'!F:F)-R7 -> 9545000 | R7: =SUMIF('PAYMENT CREDIT'!C:C,L7,'PAYMENT CREDIT'!G:G) -> 670000 | S7: =M7+Q7 -> 17305000 | T7: =N7+R7 -> 2035000 | U7: =O7 -> 355000 | V7: =SUM(S7:U7) -> 19695000 | W7: =SUMIFS('SELLING CASH'!I:I,'SELLING CASH'!C:C,L7,'SELLING CASH'!R:R,"OIL") -> 385000 | Y7: 1100000 | Z7: 180000
E8: =E6+E7 -> 15025000 | G8: Spooring | H8: =sumifs('SELLING CASH'!N:N,'SELLING CASH'!C:C,E5,'SELLING CASH'!R:R,"SERVICE")+SUMIF('SELLING CREDIT'!C:C,E5,'SELLING CREDIT'!K:K) -> 775000 | L8: 46268 | M8: =sumifs('SELLING CASH'!I:I,'SELLING CASH'!C:C,L8,'SELLING CASH'!R:R,"<>OIL")-(N8+O8+P8) -> 5465000 | N8: =sumifs('SELLING CASH'!N:N,'SELLING CASH'!C:C,L8,'SELLING CASH'!R:R,"<>SERVICE",'SELLING CASH'!R:R, "<>OIL") -> 830000 | O8: =sumifs('SELLING CASH'!N:N,'SELLING CASH'!C:C,L8,'SELLING CASH'!R:R,"SERVICE") -> 365000 | P8: =sumif('SELLING CASH'!C:C,L8,'SELLING CASH'!J:J) -> 130000 | Q8: =SUMIF('PAYMENT CREDIT'!C:C,L8,'PAYMENT CREDIT'!F:F)-R8 -> 900000 | R8: =SUMIF('PAYMENT CREDIT'!C:C,L8,'PAYMENT CREDIT'!G:G) -> 0 | S8: =M8+Q8 -> 6365000 | T8: =N8+R8 -> 830000 | U8: =O8 -> 365000 | V8: =SUM(S8:U8) -> 7560000 | W8: =SUMIFS('SELLING CASH'!I:I,'SELLING CASH'!C:C,L8,'SELLING CASH'!R:R,"OIL") -> 750000
D9: Transfer Payment | E9: =SUMif(TRANSFER!C:C,E2,TRANSFER!D:D) -> 4447000 | G9: Oil | H9: =SUMIFS('SELLING CASH'!I:I,'SELLING CASH'!C:C,E5,'SELLING CASH'!R:R,"OIL") -> 0 | L9: 46269 | M9: =sumifs('SELLING CASH'!I:I,'SELLING CASH'!C:C,L9,'SELLING CASH'!R:R,"<>OIL")-(N9+O9+P9) -> 11725000 | N9: =sumifs('SELLING CASH'!N:N,'SELLING CASH'!C:C,L9,'SELLING CASH'!R:R,"<>SERVICE",'SELLING CASH'!R:R, "<>OIL") -> 1750000 | O9: =sumifs('SELLING CASH'!N:N,'SELLING CASH'!C:C,L9,'SELLING CASH'!R:R,"SERVICE") -> 280000 | P9: =sumif('SELLING CASH'!C:C,L9,'SELLING CASH'!J:J) -> 20000 | Q9: =SUMIF('PAYMENT CREDIT'!C:C,L9,'PAYMENT CREDIT'!F:F)-R9 -> 4320000 | R9: =SUMIF('PAYMENT CREDIT'!C:C,L9,'PAYMENT CREDIT'!G:G) -> 400000 | S9: =M9+Q9 -> 16045000 | T9: =N9+R9 -> 2150000 | U9: =O9 -> 280000 | V9: =SUM(S9:U9) -> 18475000 | W9: =SUMIFS('SELLING CASH'!I:I,'SELLING CASH'!C:C,L9,'SELLING CASH'!R:R,"OIL") -> 370000
D10: Expenses | E10: =sumifS(EXPENSES!D:D,EXPENSES!C:C,E5,EXPENSES!G:G,"Cashier") -> 15000 | L10: 46270 | M10: =sumifs('SELLING CASH'!I:I,'SELLING CASH'!C:C,L10,'SELLING CASH'!R:R,"<>OIL")-(N10+O10+P10) -> 9135000 | N10: =sumifs('SELLING CASH'!N:N,'SELLING CASH'!C:C,L10,'SELLING CASH'!R:R,"<>SERVICE",'SELLING CASH'!R:R, "<>OIL") -> 835000 | O10: =sumifs('SELLING CASH'!N:N,'SELLING CASH'!C:C,L10,'SELLING CASH'!R:R,"SERVICE") -> 0 | P10: =sumif('SELLING CASH'!C:C,L10,'SELLING CASH'!J:J) -> 0 | Q10: =SUMIF('PAYMENT CREDIT'!C:C,L10,'PAYMENT CREDIT'!F:F)-R10 -> 4420000 | R10: =SUMIF('PAYMENT CREDIT'!C:C,L10,'PAYMENT CREDIT'!G:G) -> 600000 | S10: =M10+Q10 -> 13555000 | T10: =N10+R10 -> 1435000 | U10: =O10 -> 0 | V10: =SUM(S10:U10) -> 14990000 | W10: =SUMIFS('SELLING CASH'!I:I,'SELLING CASH'!C:C,L10,'SELLING CASH'!R:R,"OIL") -> 0
D11: Service Fee | E11: =sumif('SELLING CASH'!C:C,E5,'SELLING CASH'!J:J)+sumif('SELLING CREDIT'!C:C,E5,'SELLING CREDIT'!K:K) -> 125000 | G11: Detail Transfer | L11: 46271 | M11: =sumifs('SELLING CASH'!I:I,'SELLING CASH'!C:C,L11,'SELLING CASH'!R:R,"<>OIL")-(N11+O11+P11) -> 8520000 | N11: =sumifs('SELLING CASH'!N:N,'SELLING CASH'!C:C,L11,'SELLING CASH'!R:R,"<>SERVICE",'SELLING CASH'!R:R, "<>OIL") -> 1420000 | O11: =sumifs('SELLING CASH'!N:N,'SELLING CASH'!C:C,L11,'SELLING CASH'!R:R,"SERVICE") -> 480000 | P11: =sumif('SELLING CASH'!C:C,L11,'SELLING CASH'!J:J) -> 125000 | Q11: =SUMIF('PAYMENT CREDIT'!C:C,L11,'PAYMENT CREDIT'!F:F)-R11 -> 0 | R11: =SUMIF('PAYMENT CREDIT'!C:C,L11,'PAYMENT CREDIT'!G:G) -> 0 | S11: =M11+Q11 -> 8520000 | T11: =N11+R11 -> 1420000 | U11: =O11 -> 480000 | V11: =SUM(S11:U11) -> 10420000 | W11: =SUMIFS('SELLING CASH'!I:I,'SELLING CASH'!C:C,L11,'SELLING CASH'!R:R,"OIL") -> 1150000 | Y11: 75000 | Z11: 100000
D12: Nett cash | E12: =E8-(E9+E10+E11) -> 10438000 | G12: BCA | H12: =SUMIFS(TRANSFER!D:D,TRANSFER!C:C,$E$5,TRANSFER!E:E,G12) -> 3240000 | L12: 46272 | M12: =sumifs('SELLING CASH'!I:I,'SELLING CASH'!C:C,L12,'SELLING CASH'!R:R,"<>OIL")-(N12+O12+P12) -> 21520000 | N12: =sumifs('SELLING CASH'!N:N,'SELLING CASH'!C:C,L12,'SELLING CASH'!R:R,"<>SERVICE",'SELLING CASH'!R:R, "<>OIL") -> 1985000 | O12: =sumifs('SELLING CASH'!N:N,'SELLING CASH'!C:C,L12,'SELLING CASH'!R:R,"SERVICE") -> 0 | P12: =sumif('SELLING CASH'!C:C,L12,'SELLING CASH'!J:J) -> 0 | Q12: =SUMIF('PAYMENT CREDIT'!C:C,L12,'PAYMENT CREDIT'!F:F)-R12 -> 1525000 | R12: =SUMIF('PAYMENT CREDIT'!C:C,L12,'PAYMENT CREDIT'!G:G) -> 200000 | S12: =M12+Q12 -> 23045000 | T12: =N12+R12 -> 2185000 | U12: =O12 -> 0 | V12: =SUM(S12:U12) -> 25230000 | W12: =SUMIFS('SELLING CASH'!I:I,'SELLING CASH'!C:C,L12,'SELLING CASH'!R:R,"OIL") -> 0
D13: MODAL BIAN | E13: 570000 | G13: BRI | H13: =SUMIFS(TRANSFER!D:D,TRANSFER!C:C,$E$5,TRANSFER!E:E,G13) -> 0 | L13: 46273 | M13: =sumifs('SELLING CASH'!I:I,'SELLING CASH'!C:C,L13,'SELLING CASH'!R:R,"<>OIL")-(N13+O13+P13) -> 14835000 | N13: =sumifs('SELLING CASH'!N:N,'SELLING CASH'!C:C,L13,'SELLING CASH'!R:R,"<>SERVICE",'SELLING CASH'!R:R, "<>OIL") -> 1370000 | O13: =sumifs('SELLING CASH'!N:N,'SELLING CASH'!C:C,L13,'SELLING CASH'!R:R,"SERVICE") -> 520000 | P13: =sumif('SELLING CASH'!C:C,L13,'SELLING CASH'!J:J) -> 165000 | Q13: =SUMIF('PAYMENT CREDIT'!C:C,L13,'PAYMENT CREDIT'!F:F)-R13 -> 2960000 | R13: =SUMIF('PAYMENT CREDIT'!C:C,L13,'PAYMENT CREDIT'!G:G) -> 420000 | S13: =M13+Q13 -> 17795000 | T13: =N13+R13 -> 1790000 | U13: =O13 -> 520000 | V13: =SUM(S13:U13) -> 20105000 | W13: =SUMIFS('SELLING CASH'!I:I,'SELLING CASH'!C:C,L13,'SELLING CASH'!R:R,"OIL") -> 250000
D14: LABA bian | E14: 90000 | G14: DANAMON | H14: =SUMIFS(TRANSFER!D:D,TRANSFER!C:C,$E$5,TRANSFER!E:E,G14) -> 0 | L14: 46274 | M14: =sumifs('SELLING CASH'!I:I,'SELLING CASH'!C:C,L14,'SELLING CASH'!R:R,"<>OIL")-(N14+O14+P14) -> 14030000 | N14: =sumifs('SELLING CASH'!N:N,'SELLING CASH'!C:C,L14,'SELLING CASH'!R:R,"<>SERVICE",'SELLING CASH'!R:R, "<>OIL") -> 1790000 | O14: =sumifs('SELLING CASH'!N:N,'SELLING CASH'!C:C,L14,'SELLING CASH'!R:R,"SERVICE") -> 555000 | P14: =sumif('SELLING CASH'!C:C,L14,'SELLING CASH'!J:J) -> 250000 | Q14: =SUMIF('PAYMENT CREDIT'!C:C,L14,'PAYMENT CREDIT'!F:F)-R14 -> 1415000 | R14: =SUMIF('PAYMENT CREDIT'!C:C,L14,'PAYMENT CREDIT'!G:G) -> 565000 | S14: =M14+Q14 -> 15445000 | T14: =N14+R14 -> 2355000 | U14: =O14 -> 555000 | V14: =SUM(S14:U14) -> 18355000 | W14: =SUMIFS('SELLING CASH'!I:I,'SELLING CASH'!C:C,L14,'SELLING CASH'!R:R,"OIL") -> 490000 | Y14: 75000 | Z14: 100000
D15: Nett cash | E15: =E12-(E13+E14) -> 9778000 | G15: BNI | H15: =SUMIFS(TRANSFER!D:D,TRANSFER!C:C,$E$5,TRANSFER!E:E,G15) -> 0 | L15: 46275 | M15: =sumifs('SELLING CASH'!I:I,'SELLING CASH'!C:C,L15,'SELLING CASH'!R:R,"<>OIL")-(N15+O15+P15) -> 21410000 | N15: =sumifs('SELLING CASH'!N:N,'SELLING CASH'!C:C,L15,'SELLING CASH'!R:R,"<>SERVICE",'SELLING CASH'!R:R, "<>OIL") -> 3755000 | O15: =sumifs('SELLING CASH'!N:N,'SELLING CASH'!C:C,L15,'SELLING CASH'!R:R,"SERVICE") -> 895000 | P15: =sumif('SELLING CASH'!C:C,L15,'SELLING CASH'!J:J) -> 405000 | Q15: =SUMIF('PAYMENT CREDIT'!C:C,L15,'PAYMENT CREDIT'!F:F)-R15 -> 2830000 | R15: =SUMIF('PAYMENT CREDIT'!C:C,L15,'PAYMENT CREDIT'!G:G) -> 430000 | S15: =M15+Q15 -> 24240000 | T15: =N15+R15 -> 4185000 | U15: =O15 -> 895000 | V15: =SUM(S15:U15) -> 29320000 | W15: =SUMIFS('SELLING CASH'!I:I,'SELLING CASH'!C:C,L15,'SELLING CASH'!R:R,"OIL")+210000 -> 210000
G16: EDC | H16: =SUMIFS(TRANSFER!D:D,TRANSFER!C:C,$E$5,TRANSFER!E:E,G16) -> 1207000 | L16: 46276 | M16: =sumifs('SELLING CASH'!I:I,'SELLING CASH'!C:C,L16,'SELLING CASH'!R:R,"<>OIL")-(N16+O16+P16) -> 10600000 | N16: =sumifs('SELLING CASH'!N:N,'SELLING CASH'!C:C,L16,'SELLING CASH'!R:R,"<>SERVICE",'SELLING CASH'!R:R, "<>OIL") -> 1240000 | O16: =sumifs('SELLING CASH'!N:N,'SELLING CASH'!C:C,L16,'SELLING CASH'!R:R,"SERVICE") -> 190000 | P16: =sumif('SELLING CASH'!C:C,L16,'SELLING CASH'!J:J) -> 85000 | Q16: =SUMIF('PAYMENT CREDIT'!C:C,L16,'PAYMENT CREDIT'!F:F)-R16 -> 0 | R16: =SUMIF('PAYMENT CREDIT'!C:C,L16,'PAYMENT CREDIT'!G:G) -> 0 | S16: =M16+Q16 -> 10600000 | T16: =N16+R16 -> 1240000 | U16: =O16 -> 190000 | V16: =SUM(S16:U16) -> 12030000 | W16: =SUMIFS('SELLING CASH'!I:I,'SELLING CASH'!C:C,L16,'SELLING CASH'!R:R,"OIL")+360000 -> 360000
G17: QRIS | H17: =SUMIFS(TRANSFER!D:D,TRANSFER!C:C,$E$5,TRANSFER!E:E,G17) -> 0 | L17: 46277 | M17: =sumifs('SELLING CASH'!I:I,'SELLING CASH'!C:C,L17,'SELLING CASH'!R:R,"<>OIL")-(N17+O17+P17) -> 5530000 | N17: =sumifs('SELLING CASH'!N:N,'SELLING CASH'!C:C,L17,'SELLING CASH'!R:R,"<>SERVICE",'SELLING CASH'!R:R, "<>OIL") -> 735000 | O17: =sumifs('SELLING CASH'!N:N,'SELLING CASH'!C:C,L17,'SELLING CASH'!R:R,"SERVICE") -> 140000 | P17: =sumif('SELLING CASH'!C:C,L17,'SELLING CASH'!J:J) -> 10000 | Q17: =SUMIF('PAYMENT CREDIT'!C:C,L17,'PAYMENT CREDIT'!F:F)-R17 -> 1560000 | R17: =SUMIF('PAYMENT CREDIT'!C:C,L17,'PAYMENT CREDIT'!G:G) -> 200000 | S17: =M17+Q17 -> 7090000 | T17: =N17+R17 -> 935000 | U17: =O17 -> 140000 | V17: =SUM(S17:U17) -> 8165000 | W17: =SUMIFS('SELLING CASH'!I:I,'SELLING CASH'!C:C,L17,'SELLING CASH'!R:R,"OIL") -> 885000
L18: 46278 | M18: =sumifs('SELLING CASH'!I:I,'SELLING CASH'!C:C,L18,'SELLING CASH'!R:R,"<>OIL")-(N18+O18+P18) -> 0 | N18: =sumifs('SELLING CASH'!N:N,'SELLING CASH'!C:C,L18,'SELLING CASH'!R:R,"<>SERVICE",'SELLING CASH'!R:R, "<>OIL") -> 0 | O18: =sumifs('SELLING CASH'!N:N,'SELLING CASH'!C:C,L18,'SELLING CASH'!R:R,"SERVICE") -> 0 | P18: =sumif('SELLING CASH'!C:C,L18,'SELLING CASH'!J:J) -> 0 | Q18: =SUMIF('PAYMENT CREDIT'!C:C,L18,'PAYMENT CREDIT'!F:F)-R18 -> 0 | R18: =SUMIF('PAYMENT CREDIT'!C:C,L18,'PAYMENT CREDIT'!G:G) -> 0 | S18: =M18+Q18 -> 0 | T18: =N18+R18 -> 0 | U18: =O18 -> 0 | V18: =SUM(S18:U18) -> 0 | W18: =SUMIFS('SELLING CASH'!I:I,'SELLING CASH'!C:C,L18,'SELLING CASH'!R:R,"OIL") -> 0
L19: 46279 | M19: =sumifs('SELLING CASH'!I:I,'SELLING CASH'!C:C,L19,'SELLING CASH'!R:R,"<>OIL")-(N19+O19+P19) -> 3620000 | N19: =sumifs('SELLING CASH'!N:N,'SELLING CASH'!C:C,L19,'SELLING CASH'!R:R,"<>SERVICE",'SELLING CASH'!R:R, "<>OIL") -> 690000 | O19: =sumifs('SELLING CASH'!N:N,'SELLING CASH'!C:C,L19,'SELLING CASH'!R:R,"SERVICE") -> 470000 | P19: =sumif('SELLING CASH'!C:C,L19,'SELLING CASH'!J:J) -> 315000 | Q19: =SUMIF('PAYMENT CREDIT'!C:C,L19,'PAYMENT CREDIT'!F:F)-R19 -> 0 | R19: =SUMIF('PAYMENT CREDIT'!C:C,L19,'PAYMENT CREDIT'!G:G) -> 0 | S19: =M19+Q19 -> 3620000 | T19: =N19+R19 -> 690000 | U19: =O19 -> 470000 | V19: =SUM(S19:U19) -> 4780000 | W19: =SUMIFS('SELLING CASH'!I:I,'SELLING CASH'!C:C,L19,'SELLING CASH'!R:R,"OIL") -> 875000 | Y19: 150000 | Z19: 200000
L20: 46280 | M20: =sumifs('SELLING CASH'!I:I,'SELLING CASH'!C:C,L20,'SELLING CASH'!R:R,"<>OIL")-(N20+O20+P20) -> 16095000 | N20: =sumifs('SELLING CASH'!N:N,'SELLING CASH'!C:C,L20,'SELLING CASH'!R:R,"<>SERVICE",'SELLING CASH'!R:R, "<>OIL") -> 2330000 | O20: =sumifs('SELLING CASH'!N:N,'SELLING CASH'!C:C,L20,'SELLING CASH'!R:R,"SERVICE") -> 340000 | P20: =sumif('SELLING CASH'!C:C,L20,'SELLING CASH'!J:J) -> 165000 | Q20: =SUMIF('PAYMENT CREDIT'!C:C,L20,'PAYMENT CREDIT'!F:F)-R20 -> 0 | R20: =SUMIF('PAYMENT CREDIT'!C:C,L20,'PAYMENT CREDIT'!G:G) -> 0 | S20: =M20+Q20 -> 16095000 | T20: =N20+R20 -> 2330000 | U20: =O20 -> 340000 | V20: =SUM(S20:U20) -> 18765000 | W20: =SUMIFS('SELLING CASH'!I:I,'SELLING CASH'!C:C,L20,'SELLING CASH'!R:R,"OIL") -> 385000
D21: NOTE UANG THEO | E21: Jumlah | G21: Modal | H21: Laba | L21: 46281 | M21: =sumifs('SELLING CASH'!I:I,'SELLING CASH'!C:C,L21,'SELLING CASH'!R:R,"<>OIL")-(N21+O21+P21) -> 4965000 | N21: =sumifs('SELLING CASH'!N:N,'SELLING CASH'!C:C,L21,'SELLING CASH'!R:R,"<>SERVICE",'SELLING CASH'!R:R, "<>OIL") -> 943000 | O21: =sumifs('SELLING CASH'!N:N,'SELLING CASH'!C:C,L21,'SELLING CASH'!R:R,"SERVICE") -> 555000 | P21: =sumif('SELLING CASH'!C:C,L21,'SELLING CASH'!J:J) -> 310000 | Q21: =SUMIF('PAYMENT CREDIT'!C:C,L21,'PAYMENT CREDIT'!F:F)-R21 -> 0 | R21: =SUMIF('PAYMENT CREDIT'!C:C,L21,'PAYMENT CREDIT'!G:G) -> 0 | S21: =M21+Q21 -> 4965000 | T21: =N21+R21 -> 943000 | U21: =O21 -> 555000 | V21: =SUM(S21:U21) -> 6463000 | W21: =SUMIFS('SELLING CASH'!I:I,'SELLING CASH'!C:C,L21,'SELLING CASH'!R:R,"OIL") -> 525000 | Y21: 75000 | Z21: 100000
D22: 45964 | G22: =J22*75000 -> 150000 | H22: =J22*100000 -> 200000 | J22: 2 | L22: 46282 | M22: =sumifs('SELLING CASH'!I:I,'SELLING CASH'!C:C,L22,'SELLING CASH'!R:R,"<>OIL")-(N22+O22+P22) -> 14335000 | N22: =sumifs('SELLING CASH'!N:N,'SELLING CASH'!C:C,L22,'SELLING CASH'!R:R,"<>SERVICE",'SELLING CASH'!R:R, "<>OIL") -> 1740000 | O22: =sumifs('SELLING CASH'!N:N,'SELLING CASH'!C:C,L22,'SELLING CASH'!R:R,"SERVICE") -> 325000 | P22: =sumif('SELLING CASH'!C:C,L22,'SELLING CASH'!J:J) -> 150000 | Q22: =SUMIF('PAYMENT CREDIT'!C:C,L22,'PAYMENT CREDIT'!F:F)-R22 -> 0 | R22: =SUMIF('PAYMENT CREDIT'!C:C,L22,'PAYMENT CREDIT'!G:G) -> 0 | S22: =M22+Q22 -> 14335000 | T22: =N22+R22 -> 1740000 | U22: =O22 -> 325000 | V22: =SUM(S22:U22) -> 16400000 | W22: =SUMIFS('SELLING CASH'!I:I,'SELLING CASH'!C:C,L22,'SELLING CASH'!R:R,"OIL") -> 385000 | Y22: 75000 | Z22: 100000
D23: 45965 | E23: 350000 | G23: =J23*75000 -> 150000 | H23: =J23*100000 -> 200000 | J23: 2 | L23: 46283 | M23: =sumifs('SELLING CASH'!I:I,'SELLING CASH'!C:C,L23,'SELLING CASH'!R:R,"<>OIL")-(N23+O23+P23) -> 10310000 | N23: =sumifs('SELLING CASH'!N:N,'SELLING CASH'!C:C,L23,'SELLING CASH'!R:R,"<>SERVICE",'SELLING CASH'!R:R, "<>OIL") -> 1250000 | O23: =sumifs('SELLING CASH'!N:N,'SELLING CASH'!C:C,L23,'SELLING CASH'!R:R,"SERVICE") -> 440000 | P23: =sumif('SELLING CASH'!C:C,L23,'SELLING CASH'!J:J) -> 255000 | Q23: =SUMIF('PAYMENT CREDIT'!C:C,L23,'PAYMENT CREDIT'!F:F)-R23 -> 0 | R23: =SUMIF('PAYMENT CREDIT'!C:C,L23,'PAYMENT CREDIT'!G:G) -> 0 | S23: =M23+Q23 -> 10310000 | T23: =N23+R23 -> 1250000 | U23: =O23 -> 440000 | V23: =SUM(S23:U23) -> 12000000 | W23: =SUMIFS('SELLING CASH'!I:I,'SELLING CASH'!C:C,L23,'SELLING CASH'!R:R,"OIL") -> 0 | Y23: 150000 | Z23: 200000
E24: 350000 | G24: =J24*75000 -> 150000 | H24: =J24*100000 -> 200000 | J24: 2 | L24: 46284 | M24: =sumifs('SELLING CASH'!I:I,'SELLING CASH'!C:C,L24,'SELLING CASH'!R:R,"<>OIL")-(N24+O24+P24) -> 3615000 | N24: =sumifs('SELLING CASH'!N:N,'SELLING CASH'!C:C,L24,'SELLING CASH'!R:R,"<>SERVICE",'SELLING CASH'!R:R, "<>OIL") -> 810000 | O24: =sumifs('SELLING CASH'!N:N,'SELLING CASH'!C:C,L24,'SELLING CASH'!R:R,"SERVICE") -> 465000 | P24: =sumif('SELLING CASH'!C:C,L24,'SELLING CASH'!J:J) -> 225000 | Q24: =SUMIF('PAYMENT CREDIT'!C:C,L24,'PAYMENT CREDIT'!F:F)-R24 -> 13620000 | R24: =SUMIF('PAYMENT CREDIT'!C:C,L24,'PAYMENT CREDIT'!G:G) -> 1800000 | S24: =M24+Q24 -> 17235000 | T24: =N24+R24 -> 2610000 | U24: =O24 -> 465000 | V24: =SUM(S24:U24) -> 20310000 | W24: =SUMIFS('SELLING CASH'!I:I,'SELLING CASH'!C:C,L24,'SELLING CASH'!R:R,"OIL")+210000 -> 1435000 | Y24: 150000 | Z24: 200000
E25: 350000 | H25: =J25*100000 -> 200000 | J25: 2 | L25: 46285 | M25: =sumifs('SELLING CASH'!I:I,'SELLING CASH'!C:C,L25,'SELLING CASH'!R:R,"<>OIL")-(N25+O25+P25) -> 2425000 | N25: =sumifs('SELLING CASH'!N:N,'SELLING CASH'!C:C,L25,'SELLING CASH'!R:R,"<>SERVICE",'SELLING CASH'!R:R, "<>OIL") -> 375000 | O25: =sumifs('SELLING CASH'!N:N,'SELLING CASH'!C:C,L25,'SELLING CASH'!R:R,"SERVICE") -> 0 | P25: =sumif('SELLING CASH'!C:C,L25,'SELLING CASH'!J:J) -> 0 | Q25: =SUMIF('PAYMENT CREDIT'!C:C,L25,'PAYMENT CREDIT'!F:F)-R25 -> 0 | R25: =SUMIF('PAYMENT CREDIT'!C:C,L25,'PAYMENT CREDIT'!G:G) -> 0 | S25: =M25+Q25 -> 2425000 | T25: =N25+R25 -> 375000 | U25: =O25 -> 0 | V25: =SUM(S25:U25) -> 2800000 | W25: =SUMIFS('SELLING CASH'!I:I,'SELLING CASH'!C:C,L25,'SELLING CASH'!R:R,"OIL") -> 1020000
D26: 45970 | E26: 175000 | G26: =J26*75000 -> 75000 | H26: =J26*100000 -> 100000 | J26: 1 | L26: 46286 | M26: =sumifs('SELLING CASH'!I:I,'SELLING CASH'!C:C,L26,'SELLING CASH'!R:R,"<>OIL")-(N26+O26+P26) -> 5000000 | N26: =sumifs('SELLING CASH'!N:N,'SELLING CASH'!C:C,L26,'SELLING CASH'!R:R,"<>SERVICE",'SELLING CASH'!R:R, "<>OIL") -> 715000 | O26: =sumifs('SELLING CASH'!N:N,'SELLING CASH'!C:C,L26,'SELLING CASH'!R:R,"SERVICE") -> 555000 | P26: =sumif('SELLING CASH'!C:C,L26,'SELLING CASH'!J:J) -> 175000 | Q26: =SUMIF('PAYMENT CREDIT'!C:C,L26,'PAYMENT CREDIT'!F:F)-R26 -> 0 | R26: =SUMIF('PAYMENT CREDIT'!C:C,L26,'PAYMENT CREDIT'!G:G) -> 0 | S26: =M26+Q26 -> 5000000 | T26: =N26+R26 -> 715000 | U26: =O26 -> 555000 | V26: =SUM(S26:U26) -> 6270000 | W26: =SUMIFS('SELLING CASH'!I:I,'SELLING CASH'!C:C,L26,'SELLING CASH'!R:R,"OIL")+600000 -> 600000 | Y26: 150000 | Z26: 200000
D27: 45972 | E27: 350000 | G27: =J27*75000+G28 -> 225000 | H27: =J27*100000 -> 200000 | J27: 2 | L27: 46287 | M27: =sumifs('SELLING CASH'!I:I,'SELLING CASH'!C:C,L27,'SELLING CASH'!R:R,"<>OIL")-(N27+O27+P27) -> 3980000 | N27: =sumifs('SELLING CASH'!N:N,'SELLING CASH'!C:C,L27,'SELLING CASH'!R:R,"<>SERVICE",'SELLING CASH'!R:R, "<>OIL") -> 715000 | O27: =sumifs('SELLING CASH'!N:N,'SELLING CASH'!C:C,L27,'SELLING CASH'!R:R,"SERVICE") -> 590000 | P27: =sumif('SELLING CASH'!C:C,L27,'SELLING CASH'!J:J) -> 165000 | Q27: =SUMIF('PAYMENT CREDIT'!C:C,L27,'PAYMENT CREDIT'!F:F)-R27 -> 0 | R27: =SUMIF('PAYMENT CREDIT'!C:C,L27,'PAYMENT CREDIT'!G:G) -> 0 | S27: =M27+Q27 -> 3980000 | T27: =N27+R27 -> 715000 | U27: =O27 -> 590000 | V27: =SUM(S27:U27) -> 5285000 | W27: =SUMIFS('SELLING CASH'!I:I,'SELLING CASH'!C:C,L27,'SELLING CASH'!R:R,"OIL")+120000 -> 390000
D28: 45973 | E28: 175000 | G28: =J28*75000 -> 75000 | H28: =J28*100000 -> 100000 | J28: 1 | L28: 46288 | M28: =sumifs('SELLING CASH'!I:I,'SELLING CASH'!C:C,L28,'SELLING CASH'!R:R,"<>OIL")-(N28+O28+P28) -> 10125000 | N28: =sumifs('SELLING CASH'!N:N,'SELLING CASH'!C:C,L28,'SELLING CASH'!R:R,"<>SERVICE",'SELLING CASH'!R:R, "<>OIL") -> 1345000 | O28: =sumifs('SELLING CASH'!N:N,'SELLING CASH'!C:C,L28,'SELLING CASH'!R:R,"SERVICE") -> 835000 | P28: =sumif('SELLING CASH'!C:C,L28,'SELLING CASH'!J:J) -> 345000 | Q28: =SUMIF('PAYMENT CREDIT'!C:C,L28,'PAYMENT CREDIT'!F:F)-R28 -> 0 | R28: =SUMIF('PAYMENT CREDIT'!C:C,L28,'PAYMENT CREDIT'!G:G) -> 0 | S28: =M28+Q28 -> 10125000 | T28: =N28+R28 -> 1345000 | U28: =O28 -> 835000 | V28: =SUM(S28:U28) -> 12305000 | W28: =SUMIFS('SELLING CASH'!I:I,'SELLING CASH'!C:C,L28,'SELLING CASH'!R:R,"OIL") -> 1295000 | Y28: 75000 | Z28: 100000
D29: 45975 | E29: 350000 | G29: =J29*75000 -> 150000 | H29: =J29*100000 -> 200000 | J29: 2 | L29: 46289 | M29: =sumifs('SELLING CASH'!I:I,'SELLING CASH'!C:C,L29,'SELLING CASH'!R:R,"<>OIL")-(N29+O29+P29) -> 10840000 | N29: =sumifs('SELLING CASH'!N:N,'SELLING CASH'!C:C,L29,'SELLING CASH'!R:R,"<>SERVICE",'SELLING CASH'!R:R, "<>OIL") -> 1535000 | O29: =sumifs('SELLING CASH'!N:N,'SELLING CASH'!C:C,L29,'SELLING CASH'!R:R,"SERVICE") -> 540000 | P29: =sumif('SELLING CASH'!C:C,L29,'SELLING CASH'!J:J) -> 200000 | Q29: =SUMIF('PAYMENT CREDIT'!C:C,L29,'PAYMENT CREDIT'!F:F)-R29 -> 1980000 | R29: =SUMIF('PAYMENT CREDIT'!C:C,L29,'PAYMENT CREDIT'!G:G) -> 200000 | S29: =M29+Q29 -> 12820000 | T29: =N29+R29 -> 1735000 | U29: =O29 -> 540000 | V29: =SUM(S29:U29) -> 15095000 | W29: =SUMIFS('SELLING CASH'!I:I,'SELLING CASH'!C:C,L29,'SELLING CASH'!R:R,"OIL") -> 0
D30: 45978 | E30: =3*175000 -> 525000 | G30: =J30*75000 -> 225000 | H30: =J30*100000 -> 300000 | J30: 3 | L30: 46290 | M30: =sumifs('SELLING CASH'!I:I,'SELLING CASH'!C:C,L30,'SELLING CASH'!R:R,"<>OIL")-(N30+O30+P30) -> 12640000 | N30: =sumifs('SELLING CASH'!N:N,'SELLING CASH'!C:C,L30,'SELLING CASH'!R:R,"<>SERVICE",'SELLING CASH'!R:R, "<>OIL") -> 1485000 | O30: =sumifs('SELLING CASH'!N:N,'SELLING CASH'!C:C,L30,'SELLING CASH'!R:R,"SERVICE") -> 775000 | P30: =sumif('SELLING CASH'!C:C,L30,'SELLING CASH'!J:J) -> 125000 | Q30: =SUMIF('PAYMENT CREDIT'!C:C,L30,'PAYMENT CREDIT'!F:F)-R30 -> 0 | R30: =SUMIF('PAYMENT CREDIT'!C:C,L30,'PAYMENT CREDIT'!G:G) -> 0 | S30: =M30+Q30 -> 12640000 | T30: =N30+R30 -> 1485000 | U30: =O30 -> 775000 | V30: =SUM(S30:U30) -> 14900000 | W30: =SUMIFS('SELLING CASH'!I:I,'SELLING CASH'!C:C,L30,'SELLING CASH'!R:R,"OIL") -> 0
D31: 45978 | E31: 175000 | G31: =J31*75000 -> 75000 | H31: z | J31: 1 | L31: 46291 | M31: =sumifs('SELLING CASH'!I:I,'SELLING CASH'!C:C,L31,'SELLING CASH'!R:R,"<>OIL")-(N31+O31+P31) -> 0 | N31: =sumifs('SELLING CASH'!N:N,'SELLING CASH'!C:C,L31,'SELLING CASH'!R:R,"<>SERVICE",'SELLING CASH'!R:R, "<>OIL") -> 0 | O31: =sumifs('SELLING CASH'!N:N,'SELLING CASH'!C:C,L31,'SELLING CASH'!R:R,"SERVICE") -> 0 | P31: =sumif('SELLING CASH'!C:C,L31,'SELLING CASH'!J:J) -> 0 | Q31: =SUMIF('PAYMENT CREDIT'!C:C,L31,'PAYMENT CREDIT'!F:F)-R31 -> 0 | R31: =SUMIF('PAYMENT CREDIT'!C:C,L31,'PAYMENT CREDIT'!G:G) -> 0 | S31: =M31+Q31 -> 0 | T31: =N31+R31 -> 0 | U31: =O31 -> 0 | V31: =SUM(S31:U31) -> 0 | W31: =SUMIFS('SELLING CASH'!I:I,'SELLING CASH'!C:C,L31,'SELLING CASH'!R:R,"OIL") -> 0
D32: 45982 | E32: 175000 | G32: =J32*75000 -> 75000 | H32: =J32*100000 -> 100000 | J32: 1 | L32: 46292 | M32: =sumifs('SELLING CASH'!I:I,'SELLING CASH'!C:C,L32,'SELLING CASH'!R:R,"<>OIL")-(N32+O32+P32) -> 0 | N32: =sumifs('SELLING CASH'!N:N,'SELLING CASH'!C:C,L32,'SELLING CASH'!R:R,"<>SERVICE",'SELLING CASH'!R:R, "<>OIL") -> 0 | O32: =sumifs('SELLING CASH'!N:N,'SELLING CASH'!C:C,L32,'SELLING CASH'!R:R,"SERVICE") -> 0 | P32: =sumif('SELLING CASH'!C:C,L32,'SELLING CASH'!J:J) -> 0 | Q32: =SUMIF('PAYMENT CREDIT'!C:C,L32,'PAYMENT CREDIT'!F:F)-R32 -> 0 | R32: =SUMIF('PAYMENT CREDIT'!C:C,L32,'PAYMENT CREDIT'!G:G) -> 0 | S32: =M32+Q32 -> 0 | T32: =N32+R32 -> 0 | U32: =O32 -> 0 | V32: =SUM(S32:U32) -> 0 | W32: =SUMIFS('SELLING CASH'!I:I,'SELLING CASH'!C:C,L32,'SELLING CASH'!R:R,"OIL") -> 0
D33: 45983 | E33: 175000 | G33: =J33*75000 -> 75000 | H33: =J33*100000 -> 100000 | J33: 1 | L33: 46293 | M33: =sumifs('SELLING CASH'!I:I,'SELLING CASH'!C:C,L33,'SELLING CASH'!R:R,"<>OIL")-(N33+O33+P33) -> 0 | N33: =sumifs('SELLING CASH'!N:N,'SELLING CASH'!C:C,L33,'SELLING CASH'!R:R,"<>SERVICE",'SELLING CASH'!R:R, "<>OIL") -> 0 | O33: =sumifs('SELLING CASH'!N:N,'SELLING CASH'!C:C,L33,'SELLING CASH'!R:R,"SERVICE") -> 0 | P33: =sumif('SELLING CASH'!C:C,L33,'SELLING CASH'!J:J) -> 0 | Q33: =SUMIF('PAYMENT CREDIT'!C:C,L33,'PAYMENT CREDIT'!F:F)-R33 -> 0 | R33: =SUMIF('PAYMENT CREDIT'!C:C,L33,'PAYMENT CREDIT'!G:G) -> 0 | S33: =M33+Q33 -> 0 | T33: =N33+R33 -> 0 | U33: =O33 -> 0 | V33: =SUM(S33:U33) -> 0 | W33: =SUMIFS('SELLING CASH'!I:I,'SELLING CASH'!C:C,L33,'SELLING CASH'!R:R,"OIL") -> 0
D34: 45985 | E34: 200000 | G34: =J34*75000 -> 150000 | H34: =J34*100000 -> 200000 | J34: 2 | L34: 46294 | M34: =sumifs('SELLING CASH'!I:I,'SELLING CASH'!C:C,L34,'SELLING CASH'!R:R,"<>OIL")-(N34+O34+P34) -> 0 | N34: =sumifs('SELLING CASH'!N:N,'SELLING CASH'!C:C,L34,'SELLING CASH'!R:R,"<>SERVICE",'SELLING CASH'!R:R, "<>OIL") -> 0 | O34: =sumifs('SELLING CASH'!N:N,'SELLING CASH'!C:C,L34,'SELLING CASH'!R:R,"SERVICE") -> 0 | P34: =sumif('SELLING CASH'!C:C,L34,'SELLING CASH'!J:J) -> 0 | Q34: =SUMIF('PAYMENT CREDIT'!C:C,L34,'PAYMENT CREDIT'!F:F)-R34 -> 0 | R34: =SUMIF('PAYMENT CREDIT'!C:C,L34,'PAYMENT CREDIT'!G:G) -> 0 | S34: =M34+Q34 -> 0 | T34: =N34+R34 -> 0 | U34: =O34 -> 0 | V34: =SUM(S34:U34) -> 0 | W34: =SUMIFS('SELLING CASH'!I:I,'SELLING CASH'!C:C,L34,'SELLING CASH'!R:R,"OIL") -> 0
D35: 45986 | E35: 330000 | G35: 230000 | H35: =J35*100000 -> 100000 | J35: 1 | L35: 46295 | M35: =sumifs('SELLING CASH'!I:I,'SELLING CASH'!C:C,L35,'SELLING CASH'!R:R,"<>OIL")-(N35+O35+P35) -> 0 | N35: =sumifs('SELLING CASH'!N:N,'SELLING CASH'!C:C,L35,'SELLING CASH'!R:R,"<>SERVICE",'SELLING CASH'!R:R, "<>OIL") -> 0 | O35: =sumifs('SELLING CASH'!N:N,'SELLING CASH'!C:C,L35,'SELLING CASH'!R:R,"SERVICE") -> 0 | P35: =sumif('SELLING CASH'!C:C,L35,'SELLING CASH'!J:J) -> 0 | Q35: =SUMIF('PAYMENT CREDIT'!C:C,L35,'PAYMENT CREDIT'!F:F)-R35 -> 0 | R35: =SUMIF('PAYMENT CREDIT'!C:C,L35,'PAYMENT CREDIT'!G:G) -> 0 | S35: =M35+Q35 -> 0 | T35: =N35+R35 -> 0 | U35: =O35 -> 0 | V35: =SUM(S35:U35) -> 0 | W35: =SUMIFS('SELLING CASH'!I:I,'SELLING CASH'!C:C,L35,'SELLING CASH'!R:R,"OIL") -> 0
D36: 45987 | E36: 350000 | G36: =J36*75000 -> 150000 | H36: =J36*100000 -> 200000 | J36: 2 | M36: =sumifs('SELLING CASH'!I:I,'SELLING CASH'!C:C,L36,'SELLING CASH'!R:R,"<>OIL")-(N36+O36+P36) -> 0 | N36: =sumifs('SELLING CASH'!N:N,'SELLING CASH'!C:C,L36,'SELLING CASH'!R:R,"<>SERVICE",'SELLING CASH'!R:R, "<>OIL") -> 0 | O36: =sumifs('SELLING CASH'!N:N,'SELLING CASH'!C:C,L36,'SELLING CASH'!R:R,"SERVICE") -> 0 | P36: =sumif('SELLING CASH'!C:C,L36,'SELLING CASH'!J:J) -> 0 | Q36: =SUMIF('PAYMENT CREDIT'!C:C,L36,'PAYMENT CREDIT'!F:F)-R36 -> 0 | R36: =SUMIF('PAYMENT CREDIT'!C:C,L36,'PAYMENT CREDIT'!G:G) -> 0 | S36: =M36+Q36 -> 0 | T36: =N36+R36 -> 0 | U36: =O36 -> 0 | V36: =SUM(S36:U36) -> 0 | W36: =SUMIFS('SELLING CASH'!I:I,'SELLING CASH'!C:C,L36,'SELLING CASH'!R:R,"OIL") -> 0
D37: 45988 | E37: 325000 | G37: =J37*75000 -> 75000 | H37: =J37*100000 -> 100000 | J37: 1
D38: 45989 | E38: 350000 | G38: =J38*75000 -> 150000 | H38: =J38*100000 -> 200000 | J38: 2
D39: 45990 | E39: 330000 | G39: 230000 | H39: 100000 | J39: 1
D40: 45991 | E40: 175000 | G40: =J40*75000 -> 75000 | H40: =J40*100000 -> 100000 | J40: 1
...

Sheet DATABASE
C1: Item | D1: Size | E1: Tipe | F1: Brand | G1: Stock | H1: Selling Price | I1: Cost Price | J1: Owned by | K1: TAX | L1: Service Fee | M1: Category | N1: IN | O1: CASH | P1: Credit | Q1: FINAL | R1: =counta(F:F) -> 474 | V1: code | W1: Customer Name | X1: Credit | Y1: Payment | Z1: Out Standing Balance | AA1: =counta(V:V) -> 113 | AD1: D-0022 | AE1: Bapak Velg | AF1: Purchase | AG1: Payment | AH1: Out Standing Balance | AI1: =counta(AD:AD) -> 23
C2: Accelera 165/60 14 eco plush | D2: 165/60 14 | E2: eco plush | F2: Accelera | G2: 0 | H2: 535000 | I2: 431000 | J2: BIAN | K2: 1 | L2: 0 | M2: Tire | N2: =sumif(PURCHASE!I:I,C2,PURCHASE!J:J) -> 0 | O2: =sumif('SELLING CASH'!E:E,C2,'SELLING CASH'!F:F) -> 0 | P2: =sumif('SELLING CREDIT'!F:F,C2,'SELLING CREDIT'!G:G) -> 0 | Q2: =(N2+G2)-(O2+P2) -> 0 | V2: C-0001 | W2: Aartijaya Velvet | X2: =sumif('SELLING CREDIT'!E:E,W2,'SELLING CREDIT'!P:P) -> 60160000 | Y2: =sumif('PAYMENT CREDIT'!E:E,W2,'PAYMENT CREDIT'!F:F) -> 60220000 | Z2: =X2-Y2 -> -60000 | AC2: 1 | AD2: D-0001 | AE2: KHARISMA MAKMUR ABADI/PAK DADI | AF2: =sumif(PURCHASE!E:E,AE2,PURCHASE!N:N) -> 2476950800 | AG2: =sumif('PAYMENT SUPPLIER'!D:D,AE2,'PAYMENT SUPPLIER'!E:E)+sumifs(PURCHASE!N:N,PURCHASE!E:E,AE2,PURCHASE!M:M,"Cash") -> 2207165603 | AH2: =AF2-AG2 -> 269785197
C3: Accelera 165/65 13 | D3: 165/65 13 | F3: Accelera | G3: 0 | H3: 455000 | I3: 375000 | J3: BIAN | K3: 1 | L3: 0 | M3: Tire | N3: =sumif(PURCHASE!I:I,C3,PURCHASE!J:J) -> 0 | O3: =sumif('SELLING CASH'!E:E,C3,'SELLING CASH'!F:F) -> 0 | P3: =sumif('SELLING CREDIT'!F:F,C3,'SELLING CREDIT'!G:G) -> 0 | Q3: =(N3+G3)-(O3+P3) -> 0 | V3: C-0002 | W3: Bpk. Abah Agus/PACRT | X3: =sumif('SELLING CREDIT'!E:E,W3,'SELLING CREDIT'!P:P) -> 0 | Y3: =sumif('PAYMENT CREDIT'!E:E,W3,'PAYMENT CREDIT'!F:F) -> 0 | Z3: =X3-Y3 -> 0 | AC3: 1 | AD3: D-0002 | AE3: TS. SUDIRMAN/NAUFAL | AF3: =sumif(PURCHASE!E:E,AE3,PURCHASE!N:N) -> 1496642952 | AG3: =sumif('PAYMENT SUPPLIER'!D:D,AE3,'PAYMENT SUPPLIER'!E:E)+sumifs(PURCHASE!N:N,PURCHASE!E:E,AE3,PURCHASE!M:M,"Cash") -> 1350798512 | AH3: =AF3-AG3 -> 1.4584444e+08
C4: Accelera 165/80 13 | D4: 165/80 13 | F4: Accelera | G4: 0 | H4: 480000 | I4: 400000 | J4: BIAN | K4: 1 | L4: 0 | M4: Tire | N4: =sumif(PURCHASE!I:I,C4,PURCHASE!J:J) -> 0 | O4: =sumif('SELLING CASH'!E:E,C4,'SELLING CASH'!F:F) -> 0 | P4: =sumif('SELLING CREDIT'!F:F,C4,'SELLING CREDIT'!G:G) -> 0 | Q4: =(N4+G4)-(O4+P4) -> 0 | V4: C-0003 | W4: Bpk. Acep Cibeureum | X4: =sumif('SELLING CREDIT'!E:E,W4,'SELLING CREDIT'!P:P) -> 0 | Y4: =sumif('PAYMENT CREDIT'!E:E,W4,'PAYMENT CREDIT'!F:F) -> 0 | Z4: =X4-Y4 -> 0 | AC4: 1 | AD4: D-0003 | AE4: CV. MEKAR BARU/CI NOVI | AF4: =sumif(PURCHASE!E:E,AE4,PURCHASE!N:N) -> 783659910 | AG4: =sumif('PAYMENT SUPPLIER'!D:D,AE4,'PAYMENT SUPPLIER'!E:E)+sumifs(PURCHASE!N:N,PURCHASE!E:E,AE4,PURCHASE!M:M,"Cash") -> 746139510 | AH4: =AF4-AG4 -> 37520400
C5: Accelera 175/13 | D5: 175/13 | F5: Accelera | G5: 1 | H5: 640000 | I5: 531000 | J5: BIAN | K5: 1 | L5: 0 | M5: Tire | N5: =sumif(PURCHASE!I:I,C5,PURCHASE!J:J) -> 0 | O5: =sumif('SELLING CASH'!E:E,C5,'SELLING CASH'!F:F) -> 0 | P5: =sumif('SELLING CREDIT'!F:F,C5,'SELLING CREDIT'!G:G) -> 0 | Q5: =(N5+G5)-(O5+P5) -> 1 | V5: C-0004 | W5: Bpk. Aden Fahri/Cibeureum | X5: =sumif('SELLING CREDIT'!E:E,W5,'SELLING CREDIT'!P:P) -> 43810000 | Y5: =sumif('PAYMENT CREDIT'!E:E,W5,'PAYMENT CREDIT'!F:F) -> 42070000 | Z5: =X5-Y5 -> 1740000 | AC5: 1 | AD5: D-0004 | AE5: SAMUDERA GEMILANG/PAK KEMAN | AF5: =sumif(PURCHASE!E:E,AE5,PURCHASE!N:N) -> 1460388496 | AG5: =sumif('PAYMENT SUPPLIER'!D:D,AE5,'PAYMENT SUPPLIER'!E:E)+sumifs(PURCHASE!N:N,PURCHASE!E:E,AE5,PURCHASE!M:M,"Cash") -> 1323087976 | AH5: =AF5-AG5 -> 137300520
C6: Accelera 175/65 14 | D6: 175/65 14 | F6: Accelera | G6: 0 | H6: 520000 | I6: 435000 | J6: BIAN | K6: 1 | L6: 0 | M6: Tire | N6: =sumif(PURCHASE!I:I,C6,PURCHASE!J:J) -> 0 | O6: =sumif('SELLING CASH'!E:E,C6,'SELLING CASH'!F:F) -> 6 | P6: =sumif('SELLING CREDIT'!F:F,C6,'SELLING CREDIT'!G:G) -> 0 | Q6: =(N6+G6)-(O6+P6) -> -6 | V6: C-0005 | W6: Bpk. Adin Texas/Balekambang | X6: =sumif('SELLING CREDIT'!E:E,W6,'SELLING CREDIT'!P:P) -> 57435000 | Y6: =sumif('PAYMENT CREDIT'!E:E,W6,'PAYMENT CREDIT'!F:F) -> 57665000 | Z6: =X6-Y6 -> -230000 | AC6: 1 | AD6: D-0005 | AE6: MAJU BERSAMA MOTOR/ANDRI | AF6: =sumif(PURCHASE!E:E,AE6,PURCHASE!N:N) -> 7588800 | AG6: =sumif('PAYMENT SUPPLIER'!D:D,AE6,'PAYMENT SUPPLIER'!E:E)+sumifs(PURCHASE!N:N,PURCHASE!E:E,AE6,PURCHASE!M:M,"Cash") -> 7588800 | AH6: =AF6-AG6 -> 0
C7: Accelera 175/70 13 | D7: 175/70 13 | F7: Accelera | G7: 0 | H7: 475000 | I7: 395000 | J7: BIAN | K7: 1 | L7: 0 | M7: Tire | N7: =sumif(PURCHASE!I:I,C7,PURCHASE!J:J) -> 0 | O7: =sumif('SELLING CASH'!E:E,C7,'SELLING CASH'!F:F) -> 0 | P7: =sumif('SELLING CREDIT'!F:F,C7,'SELLING CREDIT'!G:G) -> 0 | Q7: =(N7+G7)-(O7+P7) -> 0 | V7: C-0006 | W7: Bpk. Agus Antasalam | X7: =sumif('SELLING CREDIT'!E:E,W7,'SELLING CREDIT'!P:P) -> 22030000 | Y7: =sumif('PAYMENT CREDIT'!E:E,W7,'PAYMENT CREDIT'!F:F) -> 22030000 | Z7: =X7-Y7 -> 0 | AC7: 1 | AD7: D-0006 | AE7: MUSTIKA ADI SEJAHTERA/PAK TEDDY | AF7: =sumif(PURCHASE!E:E,AE7,PURCHASE!N:N) -> 0 | AG7: =sumif('PAYMENT SUPPLIER'!D:D,AE7,'PAYMENT SUPPLIER'!E:E)+sumifs(PURCHASE!N:N,PURCHASE!E:E,AE7,PURCHASE!M:M,"Cash") -> 34845000 | AH7: =AF7-AG7 -> -34845000
C8: Accelera 185/14 | D8: 185/14 | F8: Accelera | G8: 0 | H8: 700000 | I8: 600000 | J8: BIAN | K8: 1 | L8: 0 | M8: Tire | N8: =sumif(PURCHASE!I:I,C8,PURCHASE!J:J) -> 0 | O8: =sumif('SELLING CASH'!E:E,C8,'SELLING CASH'!F:F) -> 0 | P8: =sumif('SELLING CREDIT'!F:F,C8,'SELLING CREDIT'!G:G) -> 0 | Q8: =(N8+G8)-(O8+P8) -> 0 | V8: C-0007 | W8: Bpk. Aji Cibodas Solokan jeruk | X8: =sumif('SELLING CREDIT'!E:E,W8,'SELLING CREDIT'!P:P) -> 0 | Y8: =sumif('PAYMENT CREDIT'!E:E,W8,'PAYMENT CREDIT'!F:F) -> 0 | Z8: =X8-Y8 -> 0 | AC8: 1 | AD8: D-0007 | AE8: CV. KHARISMA TIARA ABADI/DICKY | AF8: =sumif(PURCHASE!E:E,AE8,PURCHASE!N:N) -> 38011500 | AG8: =sumif('PAYMENT SUPPLIER'!D:D,AE8,'PAYMENT SUPPLIER'!E:E)+sumifs(PURCHASE!N:N,PURCHASE!E:E,AE8,PURCHASE!M:M,"Cash") -> 38011500 | AH8: =AF8-AG8 -> 0
C9: Accelera 185/70 14 | D9: 185/70 14 | F9: Accelera | G9: 10 | H9: 600000 | I9: 483960 | J9: BIAN | K9: 1 | L9: 0 | M9: Tire | N9: =sumif(PURCHASE!I:I,C9,PURCHASE!J:J) -> 0 | O9: =sumif('SELLING CASH'!E:E,C9,'SELLING CASH'!F:F) -> 10 | P9: =sumif('SELLING CREDIT'!F:F,C9,'SELLING CREDIT'!G:G) -> 0 | Q9: =(N9+G9)-(O9+P9) -> 0 | V9: C-0008 | W9: Bpk. Amal Cikawao | X9: =sumif('SELLING CREDIT'!E:E,W9,'SELLING CREDIT'!P:P) -> 4500000 | Y9: =sumif('PAYMENT CREDIT'!E:E,W9,'PAYMENT CREDIT'!F:F) -> 4500000 | Z9: =X9-Y9 -> 0 | AC9: 1 | AD9: D-0008 | AE9: PT. INDOTYRE MANDIRI SENTOSA | AF9: =sumif(PURCHASE!E:E,AE9,PURCHASE!N:N) -> 2457540 | AG9: =sumif('PAYMENT SUPPLIER'!D:D,AE9,'PAYMENT SUPPLIER'!E:E)+sumifs(PURCHASE!N:N,PURCHASE!E:E,AE9,PURCHASE!M:M,"Cash") -> 2457540 | AH9: =AF9-AG9 -> 0
C10: Accelera 195/15 | D10: 195/15 | F10: Accelera | G10: 3 | H10: 820000 | I10: 730000 | J10: BIAN | K10: 1 | L10: 0 | M10: Tire | N10: =sumif(PURCHASE!I:I,C10,PURCHASE!J:J) -> 0 | O10: =sumif('SELLING CASH'!E:E,C10,'SELLING CASH'!F:F) -> 0 | P10: =sumif('SELLING CREDIT'!F:F,C10,'SELLING CREDIT'!G:G) -> 0 | Q10: =(N10+G10)-(O10+P10) -> 3 | V10: C-0009 | W10: Bpk. Asep PSB/CIbeureum | X10: =sumif('SELLING CREDIT'!E:E,W10,'SELLING CREDIT'!P:P) -> 0 | Y10: =sumif('PAYMENT CREDIT'!E:E,W10,'PAYMENT CREDIT'!F:F) -> 0 | Z10: =X10-Y10 -> 0 | AC10: 1 | AD10: D-0009 | AE10: CV. MULTIPRIMA INTI NUSANTARA | AF10: =sumif(PURCHASE!E:E,AE10,PURCHASE!N:N) -> 107077000 | AG10: =sumif('PAYMENT SUPPLIER'!D:D,AE10,'PAYMENT SUPPLIER'!E:E)+sumifs(PURCHASE!N:N,PURCHASE!E:E,AE10,PURCHASE!M:M,"Cash") -> 107077000 | AH10: =AF10-AG10 -> 0
C11: Accelera 205/40 17 | D11: 205/40 17 | F11: Accelera | G11: 0 | H11: 820000 | I11: 690000 | J11: BIAN | K11: 1 | L11: 0 | M11: Tire | N11: =sumif(PURCHASE!I:I,C11,PURCHASE!J:J) -> 0 | O11: =sumif('SELLING CASH'!E:E,C11,'SELLING CASH'!F:F) -> 0 | P11: =sumif('SELLING CREDIT'!F:F,C11,'SELLING CREDIT'!G:G) -> 0 | Q11: =(N11+G11)-(O11+P11) -> 0 | V11: C-0010 | W11: Bpk. Bram | X11: =sumif('SELLING CREDIT'!E:E,W11,'SELLING CREDIT'!P:P) -> 37170000 | Y11: =sumif('PAYMENT CREDIT'!E:E,W11,'PAYMENT CREDIT'!F:F) -> 37270000 | Z11: =X11-Y11 -> -100000 | AC11: 1 | AD11: D-0010 | AE11: PT. DIRGAPUTRA EKAPRATAMA | AF11: =sumif(PURCHASE!E:E,AE11,PURCHASE!N:N) -> 68524013 | AG11: =sumif('PAYMENT SUPPLIER'!D:D,AE11,'PAYMENT SUPPLIER'!E:E)+sumifs(PURCHASE!N:N,PURCHASE!E:E,AE11,PURCHASE!M:M,"Cash") -> 57836381 | AH11: =AF11-AG11 -> 10687632
C12: ACCELERA 215/35 18 SIGMA | D12: 215/35 18 | E12: SIGMA | F12: ACCELERA | G12: 0 | H12: 870000 | I12: 760239 | J12: BIAN | K12: 1 | L12: 0 | M12: Tire | N12: =sumif(PURCHASE!I:I,C12,PURCHASE!J:J) -> 1 | O12: =sumif('SELLING CASH'!E:E,C12,'SELLING CASH'!F:F) -> 1 | P12: =sumif('SELLING CREDIT'!F:F,C12,'SELLING CREDIT'!G:G) -> 0 | Q12: =(N12+G12)-(O12+P12) -> 0 | V12: C-0011 | W12: Bpk. Cuplis | X12: =sumif('SELLING CREDIT'!E:E,W12,'SELLING CREDIT'!P:P) -> 26690000 | Y12: =sumif('PAYMENT CREDIT'!E:E,W12,'PAYMENT CREDIT'!F:F) -> 23840000 | Z12: =X12-Y12 -> 2850000 | AC12: 1 | AD12: D-0011 | AE12: CV. MEKAR PRATAMA BAN | AF12: =sumif(PURCHASE!E:E,AE12,PURCHASE!N:N) -> 0 | AG12: =sumif('PAYMENT SUPPLIER'!D:D,AE12,'PAYMENT SUPPLIER'!E:E)+sumifs(PURCHASE!N:N,PURCHASE!E:E,AE12,PURCHASE!M:M,"Cash") -> 0 | AH12: =AF12-AG12 -> 0
C13: Accelera 215/55 17 | D13: 215/55 17 | F13: Accelera | G13: 0 | H13: 930000 | I13: 805000 | J13: BIAN | K13: 1 | L13: 0 | M13: Tire | N13: =sumif(PURCHASE!I:I,C13,PURCHASE!J:J) -> 1 | O13: =sumif('SELLING CASH'!E:E,C13,'SELLING CASH'!F:F) -> 1 | P13: =sumif('SELLING CREDIT'!F:F,C13,'SELLING CREDIT'!G:G) -> 0 | Q13: =(N13+G13)-(O13+P13) -> 0 | V13: C-0012 | W13: Bpk. Dani Darmawan/Garduh Jaya | X13: =sumif('SELLING CREDIT'!E:E,W13,'SELLING CREDIT'!P:P) -> 33145000 | Y13: =sumif('PAYMENT CREDIT'!E:E,W13,'PAYMENT CREDIT'!F:F) -> 33145000 | Z13: =X13-Y13 -> 0 | AC13: 1 | AD13: D-0012 | AE13: PT. Astra Otoparts Tbk | AF13: =sumif(PURCHASE!E:E,AE13,PURCHASE!N:N) -> 11909978 | AG13: =sumif('PAYMENT SUPPLIER'!D:D,AE13,'PAYMENT SUPPLIER'!E:E)+sumifs(PURCHASE!N:N,PURCHASE!E:E,AE13,PURCHASE!M:M,"Cash") -> 12288515 | AH13: =AF13-AG13 -> -378537
C14: Accelera 225/40 19 | D14: 225/40 19 | F14: Accelera | G14: 0 | H14: 1270000 | I14: 1117000 | J14: BIAN | K14: 1 | L14: 0 | M14: Tire | N14: =sumif(PURCHASE!I:I,C14,PURCHASE!J:J) -> 0 | O14: =sumif('SELLING CASH'!E:E,C14,'SELLING CASH'!F:F) -> 0 | P14: =sumif('SELLING CREDIT'!F:F,C14,'SELLING CREDIT'!G:G) -> 0 | Q14: =(N14+G14)-(O14+P14) -> 0 | V14: C-0013 | W14: Bpk. Dani Jembar Mukti | X14: =sumif('SELLING CREDIT'!E:E,W14,'SELLING CREDIT'!P:P) -> 18830000 | Y14: =sumif('PAYMENT CREDIT'!E:E,W14,'PAYMENT CREDIT'!F:F) -> 18830000 | Z14: =X14-Y14 -> 0 | AC14: 1 | AD14: D-0013 | AE14: PT. DAYTECH TETRA SINDO | AF14: =sumif(PURCHASE!E:E,AE14,PURCHASE!N:N) -> 3683000 | AG14: =sumif('PAYMENT SUPPLIER'!D:D,AE14,'PAYMENT SUPPLIER'!E:E)+sumifs(PURCHASE!N:N,PURCHASE!E:E,AE14,PURCHASE!M:M,"Cash") -> 3683000 | AH14: =AF14-AG14 -> 0
C15: Accelera 235/75 15 at omicron | D15: 235/75 15 | E15: omicron at | F15: Accelera | G15: 0 | H15: 1040000 | I15: 920000 | J15: BIAN | K15: 1 | L15: 0 | M15: Tire | N15: =sumif(PURCHASE!I:I,C15,PURCHASE!J:J) -> 1 | O15: =sumif('SELLING CASH'!E:E,C15,'SELLING CASH'!F:F) -> 1 | P15: =sumif('SELLING CREDIT'!F:F,C15,'SELLING CREDIT'!G:G) -> 0 | Q15: =(N15+G15)-(O15+P15) -> 0 | V15: C-0014 | W15: Bpk. Dede DP/Pasanggrahan | X15: =sumif('SELLING CREDIT'!E:E,W15,'SELLING CREDIT'!P:P) -> 10180000 | Y15: =sumif('PAYMENT CREDIT'!E:E,W15,'PAYMENT CREDIT'!F:F) -> 10180000 | Z15: =X15-Y15 -> 0 | AC15: 1 | AD15: D-0014 | AE15: PT. RODA ARTHA | AF15: =sumif(PURCHASE!E:E,AE15,PURCHASE!N:N) -> 1181180000 | AG15: =sumif('PAYMENT SUPPLIER'!D:D,AE15,'PAYMENT SUPPLIER'!E:E)+sumifs(PURCHASE!N:N,PURCHASE!E:E,AE15,PURCHASE!M:M,"Cash") -> 977975000 | AH15: =AF15-AG15 -> 203205000
C16: =F16&" "&D16&" "&E16 -> Advance 1000/20 GL662A+ | D16: 1000/20 | E16: GL662A+ | F16: Advance | G16: 0 | H16: 4450000 | I16: 4200000 | J16: BIAN | K16: 1 | L16: 0 | M16: Tire | N16: =sumif(PURCHASE!I:I,C16,PURCHASE!J:J) -> 5 | O16: =sumif('SELLING CASH'!E:E,C16,'SELLING CASH'!F:F) -> 6 | P16: =sumif('SELLING CREDIT'!F:F,C16,'SELLING CREDIT'!G:G) -> 0 | Q16: =(N16+G16)-(O16+P16) -> -1 | V16: C-0015 | W16: Bpk. Deden Putra Walahir | X16: =sumif('SELLING CREDIT'!E:E,W16,'SELLING CREDIT'!P:P) -> 77230000 | Y16: =sumif('PAYMENT CREDIT'!E:E,W16,'PAYMENT CREDIT'!F:F) -> 74690000 | Z16: =X16-Y16 -> 2540000 | AC16: 1 | AD16: D-0015 | AE16: PT. RODA GAMA | AF16: =sumif(PURCHASE!E:E,AE16,PURCHASE!N:N) -> 53192000 | AG16: =sumif('PAYMENT SUPPLIER'!D:D,AE16,'PAYMENT SUPPLIER'!E:E)+sumifs(PURCHASE!N:N,PURCHASE!E:E,AE16,PURCHASE!M:M,"Cash") -> 54948000 | AH16: =AF16-AG16 -> -1756000
C17: Advance 750/15 radial fullset | D17: 750/15 | E17: radial fullset | F17: Advance | G17: 0 | H17: 1865000 | I17: 1765000 | J17: BIAN | K17: 1 | L17: 0 | M17: Tire | N17: =sumif(PURCHASE!I:I,C17,PURCHASE!J:J) -> 2 | O17: =sumif('SELLING CASH'!E:E,C17,'SELLING CASH'!F:F) -> 2 | P17: =sumif('SELLING CREDIT'!F:F,C17,'SELLING CREDIT'!G:G) -> 1 | Q17: =(N17+G17)-(O17+P17) -> -1 | V17: C-0016 | W17: Bpk. Deden Putra Walahir | X17: =sumif('SELLING CREDIT'!E:E,W17,'SELLING CREDIT'!P:P) -> 77230000 | Y17: =sumif('PAYMENT CREDIT'!E:E,W17,'PAYMENT CREDIT'!F:F) -> 74690000 | Z17: =X17-Y17 -> 2540000 | AC17: 1 | AD17: D-0016 | AE17: PT. VETRON SAILUN | AF17: =sumif(PURCHASE!E:E,AE17,PURCHASE!N:N) -> 61608400 | AG17: =sumif('PAYMENT SUPPLIER'!D:D,AE17,'PAYMENT SUPPLIER'!E:E)+sumifs(PURCHASE!N:N,PURCHASE!E:E,AE17,PURCHASE!M:M,"Cash") -> 57448400 | AH17: =AF17-AG17 -> 4160000
C18: ADVANCE 750/16 GL279A+ CACING | D18: 750/16 | E18: GL279A+ CACING | F18: ADVANCE | G18: 1 | H18: 1950000 | I18: 1840000 | J18: BIAN | K18: 1 | L18: 0 | M18: Tire | N18: =sumif(PURCHASE!I:I,C18,PURCHASE!J:J) -> 0 | O18: =sumif('SELLING CASH'!E:E,C18,'SELLING CASH'!F:F) -> 1 | P18: =sumif('SELLING CREDIT'!F:F,C18,'SELLING CREDIT'!G:G) -> 0 | Q18: =(N18+G18)-(O18+P18) -> 0 | V18: C-0017 | W18: Bpk. Dedi CRW | X18: =sumif('SELLING CREDIT'!E:E,W18,'SELLING CREDIT'!P:P) -> 6170000 | Y18: =sumif('PAYMENT CREDIT'!E:E,W18,'PAYMENT CREDIT'!F:F) -> 6170000 | Z18: =X18-Y18 -> 0 | AC18: 1 | AD18: D-0017 | AE18: PT BANCORE SENTRAL UTAMA | AF18: =sumif(PURCHASE!E:E,AE18,PURCHASE!N:N) -> 71382000 | AG18: =sumif('PAYMENT SUPPLIER'!D:D,AE18,'PAYMENT SUPPLIER'!E:E)+sumifs(PURCHASE!N:N,PURCHASE!E:E,AE18,PURCHASE!M:M,"Cash") -> 62414000 | AH18: =AF18-AG18 -> 8968000
C19: Advance 750/16 GL672D | D19: 750/16 | E19: G72D | F19: Advance | G19: 4 | H19: 2080000 | I19: 1980000 | J19: BIAN | K19: 1 | L19: 0 | M19: Tire | N19: =sumif(PURCHASE!I:I,C19,PURCHASE!J:J) -> 135 | O19: =sumif('SELLING CASH'!E:E,C19,'SELLING CASH'!F:F) -> 31 | P19: =sumif('SELLING CREDIT'!F:F,C19,'SELLING CREDIT'!G:G) -> 115 | Q19: =(N19+G19)-(O19+P19) -> -7 | V19: C-0018 | W19: Bpk. Dinar Sudi | X19: =sumif('SELLING CREDIT'!E:E,W19,'SELLING CREDIT'!P:P) -> 31250000 | Y19: =sumif('PAYMENT CREDIT'!E:E,W19,'PAYMENT CREDIT'!F:F) -> 31250000 | Z19: =X19-Y19 -> 0 | AC19: 1 | AD19: D-0018 | AE19: PT. Prestasi Pelumasindo Unggul | AF19: =sumif(PURCHASE!E:E,AE19,PURCHASE!N:N) -> 90698229 | AG19: =sumif('PAYMENT SUPPLIER'!D:D,AE19,'PAYMENT SUPPLIER'!E:E)+sumifs(PURCHASE!N:N,PURCHASE!E:E,AE19,PURCHASE!M:M,"Cash") -> 20137800 | AH19: =AF19-AG19 -> 70560429
C20: Advance 750/16 GLG71A+ | D20: 750/16 | E20: GL71A+ | F20: Advance | G20: 8 | H20: 1985000 | I20: 1885000 | J20: BIAN | K20: 1 | L20: 0 | M20: Tire | N20: =sumif(PURCHASE!I:I,C20,PURCHASE!J:J) -> 113 | O20: =sumif('SELLING CASH'!E:E,C20,'SELLING CASH'!F:F) -> 40 | P20: =sumif('SELLING CREDIT'!F:F,C20,'SELLING CREDIT'!G:G) -> 81 | Q20: =(N20+G20)-(O20+P20) -> 0 | V20: C-0019 | W20: Bpk. Dudung Cikoneng | X20: =sumif('SELLING CREDIT'!E:E,W20,'SELLING CREDIT'!P:P) -> 10195000 | Y20: =sumif('PAYMENT CREDIT'!E:E,W20,'PAYMENT CREDIT'!F:F) -> 10195000 | Z20: =X20-Y20 -> 0 | AC20: 1 | AD20: D-0019 | AE20: PT. Limas Raga Inti | AF20: =sumif(PURCHASE!E:E,AE20,PURCHASE!N:N) -> 11745923 | AG20: =sumif('PAYMENT SUPPLIER'!D:D,AE20,'PAYMENT SUPPLIER'!E:E)+sumifs(PURCHASE!N:N,PURCHASE!E:E,AE20,PURCHASE!M:M,"Cash") -> 9760000 | AH20: =AF20-AG20 -> 1985923.1
C21: Advance 750/16 k. tahu GL909A | D21: 750/16 | E21: GL909A | F21: Advance | G21: 12 | H21: 2260000 | I21: 2160000 | J21: BIAN | K21: 1 | L21: 0 | M21: Tire | N21: =sumif(PURCHASE!I:I,C21,PURCHASE!J:J) -> 152 | O21: =sumif('SELLING CASH'!E:E,C21,'SELLING CASH'!F:F) -> 28 | P21: =sumif('SELLING CREDIT'!F:F,C21,'SELLING CREDIT'!G:G) -> 126 | Q21: =(N21+G21)-(O21+P21) -> 10 | V21: C-0020 | W21: Bpk. Egi/Ganjar Pasirkukun | X21: =sumif('SELLING CREDIT'!E:E,W21,'SELLING CREDIT'!P:P) -> 7750000 | Y21: =sumif('PAYMENT CREDIT'!E:E,W21,'PAYMENT CREDIT'!F:F) -> 5950000 | Z21: =X21-Y21 -> 1800000 | AC21: 1 | AD21: D-0020 | AE21: Pak Wang Pentil | AF21: =sumif(PURCHASE!E:E,AE21,PURCHASE!N:N) -> 13942000 | AG21: =sumif('PAYMENT SUPPLIER'!D:D,AE21,'PAYMENT SUPPLIER'!E:E)+sumifs(PURCHASE!N:N,PURCHASE!E:E,AE21,PURCHASE!M:M,"Cash") -> 18149500 | AH21: =AF21-AG21 -> -4207500
C22: Aeolus 750/16 | D22: 750/16 | F22: Aeolus | G22: 0 | H22: 2200000 | I22: 2050000 | J22: BIAN | K22: 0 | L22: 0 | M22: Tire | N22: =sumif(PURCHASE!I:I,C22,PURCHASE!J:J) -> 0 | O22: =sumif('SELLING CASH'!E:E,C22,'SELLING CASH'!F:F) -> 0 | P22: =sumif('SELLING CREDIT'!F:F,C22,'SELLING CREDIT'!G:G) -> 0 | Q22: =(N22+G22)-(O22+P22) -> 0 | V22: C-0021 | W22: Bpk. Endang RSJ Sudi | X22: =sumif('SELLING CREDIT'!E:E,W22,'SELLING CREDIT'!P:P) -> 62285000 | Y22: =sumif('PAYMENT CREDIT'!E:E,W22,'PAYMENT CREDIT'!F:F) -> 64055000 | Z22: =X22-Y22 -> -1770000 | AC22: 1 | AD22: D-0021 | AE22: PT. Arta Batrindo | AF22: =sumif(PURCHASE!E:E,AE22,PURCHASE!N:N) -> 5000000 | AG22: =sumif('PAYMENT SUPPLIER'!D:D,AE22,'PAYMENT SUPPLIER'!E:E)+sumifs(PURCHASE!N:N,PURCHASE!E:E,AE22,PURCHASE!M:M,"Cash") -> 5000000 | AH22: =AF22-AG22 -> 0
C23: =F23&" "&D23&" "&E23 -> Aspira Filter Oli Avaza-Agya | E23: Filter Oli Avaza-Agya | F23: Aspira | G23: 0 | H23: 25000 | I23: 19200 | J23: BIAN | K23: 0 | L23: 0 | M23: COMPLEMENTARY | N23: =sumif(PURCHASE!I:I,C23,PURCHASE!J:J) -> 20 | O23: =sumif('SELLING CASH'!E:E,C23,'SELLING CASH'!F:F) -> 56 | P23: =sumif('SELLING CREDIT'!F:F,C23,'SELLING CREDIT'!G:G) -> 0 | Q23: =(N23+G23)-(O23+P23) -> -36 | V23: C-0022 | W23: Bpk. Eye | X23: =sumif('SELLING CREDIT'!E:E,W23,'SELLING CREDIT'!P:P) -> 3495000 | Y23: =sumif('PAYMENT CREDIT'!E:E,W23,'PAYMENT CREDIT'!F:F) -> 2985000 | Z23: =X23-Y23 -> 510000 | AD23: D-0022 | AE23: SURYA LESTARI/PAK IWAN | AF23: =sumif(PURCHASE!E:E,AE23,PURCHASE!N:N) -> 5159200 | AG23: =sumif('PAYMENT SUPPLIER'!D:D,AE23,'PAYMENT SUPPLIER'!E:E)+sumifs(PURCHASE!N:N,PURCHASE!E:E,AE23,PURCHASE!O:O,"LUNAS") -> 3813500 | AH23: =AF23-AG23 -> 1345700
C24: Aspira 750/16 Halus | D24: 750/16 | E24: Halus | F24: Aspira | G24: 0 | H24: 1730000 | I24: 1610000 | J24: BIAN | K24: 0 | L24: 0 | M24: Tire | N24: =sumif(PURCHASE!I:I,C24,PURCHASE!J:J) -> 2 | O24: =sumif('SELLING CASH'!E:E,C24,'SELLING CASH'!F:F) -> 0 | P24: =sumif('SELLING CREDIT'!F:F,C24,'SELLING CREDIT'!G:G) -> 3 | Q24: =(N24+G24)-(O24+P24) -> -1 | V24: C-0023 | W24: Bpk. Fauzan | X24: =sumif('SELLING CREDIT'!E:E,W24,'SELLING CREDIT'!P:P) -> 0 | Y24: =sumif('PAYMENT CREDIT'!E:E,W24,'PAYMENT CREDIT'!F:F) -> 0 | Z24: =X24-Y24 -> 0
C25: Aspira 750/16 Kasar | D25: 750/16 | E25: Kasar | F25: Aspira | G25: 0 | H25: 1850000 | I25: 1725000 | J25: BIAN | K25: 0 | L25: 0 | M25: Tire | N25: =sumif(PURCHASE!I:I,C25,PURCHASE!J:J) -> 0 | O25: =sumif('SELLING CASH'!E:E,C25,'SELLING CASH'!F:F) -> 1 | P25: =sumif('SELLING CREDIT'!F:F,C25,'SELLING CREDIT'!G:G) -> 1 | Q25: =(N25+G25)-(O25+P25) -> -2 | V25: C-0024 | W25: Bpk. H Entang | X25: =sumif('SELLING CREDIT'!E:E,W25,'SELLING CREDIT'!P:P) -> 70800000 | Y25: =sumif('PAYMENT CREDIT'!E:E,W25,'PAYMENT CREDIT'!F:F) -> 68210000 | Z25: =X25-Y25 -> 2590000
C26: Balancing 30 | D26: - | F26: Balancing | G26: 100000 | H26: 30000 | I26: 10000 | J26: BIAN | K26: 0 | L26: 0 | M26: COMPLEMENTARY | N26: =sumif(PURCHASE!I:I,C26,PURCHASE!J:J) -> 205 | O26: =sumif('SELLING CASH'!E:E,C26,'SELLING CASH'!F:F) -> 1858 | P26: =sumif('SELLING CREDIT'!F:F,C26,'SELLING CREDIT'!G:G) -> 12 | Q26: =(N26+G26)-(O26+P26) -> 98335 | V26: C-0025 | W26: Bpk. H Odang Pelered | X26: =sumif('SELLING CREDIT'!E:E,W26,'SELLING CREDIT'!P:P) -> 6855000 | Y26: =sumif('PAYMENT CREDIT'!E:E,W26,'PAYMENT CREDIT'!F:F) -> 5975000 | Z26: =X26-Y26 -> 880000
C27: Balancing 60 | D27: -- | F27: Balancing | G27: 9997344 | H27: 60000 | I27: 15000 | J27: BIAN | K27: 0 | L27: 0 | M27: COMPLEMENTARY | N27: =sumif(PURCHASE!I:I,C27,PURCHASE!J:J) -> 0 | O27: =sumif('SELLING CASH'!E:E,C27,'SELLING CASH'!F:F) -> 21 | P27: =sumif('SELLING CREDIT'!F:F,C27,'SELLING CREDIT'!G:G) -> 4 | Q27: =(N27+G27)-(O27+P27) -> 9997319 | V27: C-0026 | W27: Bpk. H. Alit Cibeureum | X27: =sumif('SELLING CREDIT'!E:E,W27,'SELLING CREDIT'!P:P) -> 10980000 | Y27: =sumif('PAYMENT CREDIT'!E:E,W27,'PAYMENT CREDIT'!F:F) -> 10980000 | Z27: =X27-Y27 -> 0
C28: Baut Camber | D28: - | F28: Baut Camber | G28: 360 | H28: 250000 | I28: 75000 | J28: BIAN | K28: 0 | L28: 75000 | M28: COMPLEMENTARY | N28: =sumif(PURCHASE!I:I,C28,PURCHASE!J:J) -> 259 | O28: =sumif('SELLING CASH'!E:E,C28,'SELLING CASH'!F:F) -> 585 | P28: =sumif('SELLING CREDIT'!F:F,C28,'SELLING CREDIT'!G:G) -> 2 | Q28: =(N28+G28)-(O28+P28) -> 32 | V28: C-0027 | W28: Bpk. H. Amin Cibeureum | X28: =sumif('SELLING CREDIT'!E:E,W28,'SELLING CREDIT'!P:P) -> 99660000 | Y28: =sumif('PAYMENT CREDIT'!E:E,W28,'PAYMENT CREDIT'!F:F) -> 99660000 | Z28: =X28-Y28 -> 0
C29: Baut Camber 17 | D29: - | F29: Baut Camber 17 | G29: 999285 | H29: 250000 | I29: 75000 | J29: BIAN | K29: 0 | L29: 75000 | M29: COMPLEMENTARY | N29: =sumif(PURCHASE!I:I,C29,PURCHASE!J:J) -> 0 | O29: =sumif('SELLING CASH'!E:E,C29,'SELLING CASH'!F:F) -> 0 | P29: =sumif('SELLING CREDIT'!F:F,C29,'SELLING CREDIT'!G:G) -> 0 | Q29: =(N29+G29)-(O29+P29) -> 999285 | V29: C-0028 | W29: Bpk. H. Anang/Ciparay barujati | X29: =sumif('SELLING CREDIT'!E:E,W29,'SELLING CREDIT'!P:P) -> 2010000 | Y29: =sumif('PAYMENT CREDIT'!E:E,W29,'PAYMENT CREDIT'!F:F) -> 2010000 | Z29: =X29-Y29 -> 0
C30: Baut Camber ss-carry | D30: - | F30: Baut Camber ss-carry | G30: 10000 | H30: 200000 | I30: 75000 | J30: BIAN | K30: 0 | L30: 25000 | M30: COMPLEMENTARY | N30: =sumif(PURCHASE!I:I,C30,PURCHASE!J:J) -> 0 | O30: =sumif('SELLING CASH'!E:E,C30,'SELLING CASH'!F:F) -> 156 | P30: =sumif('SELLING CREDIT'!F:F,C30,'SELLING CREDIT'!G:G) -> 1 | Q30: =(N30+G30)-(O30+P30) -> 9843 | V30: C-0029 | W30: Bpk. H. Ikhsan/Cibeureum | X30: =sumif('SELLING CREDIT'!E:E,W30,'SELLING CREDIT'!P:P) -> 77200000 | Y30: =sumif('PAYMENT CREDIT'!E:E,W30,'PAYMENT CREDIT'!F:F) -> 68980000 | Z30: =X30-Y30 -> 8220000
C31: Baut Roda 12x1.5 | D31: - | F31: Baut | G31: 0 | H31: 15000 | I31: 10000 | J31: IBU | K31: 0 | L31: 0 | M31: COMPLEMENTARY | N31: =sumif(PURCHASE!I:I,C31,PURCHASE!J:J) -> 0 | O31: =sumif('SELLING CASH'!E:E,C31,'SELLING CASH'!F:F) -> 49 | P31: =sumif('SELLING CREDIT'!F:F,C31,'SELLING CREDIT'!G:G) -> 0 | Q31: =(N31+G31)-(O31+P31) -> -49 | V31: C-0030 | W31: Bpk. H. Iwan | X31: =sumif('SELLING CREDIT'!E:E,W31,'SELLING CREDIT'!P:P) -> 4300000 | Y31: =sumif('PAYMENT CREDIT'!E:E,W31,'PAYMENT CREDIT'!F:F) -> 4300000 | Z31: =X31-Y31 -> 0
C32: BD 1000 Bridgestone | D32: 1000 | E32: Bridgestone | F32: BD | G32: 2 | H32: 600000 | I32: 535000 | J32: IBU | K32: 1 | L32: 0 | M32: Tire | N32: =sumif(PURCHASE!I:I,C32,PURCHASE!J:J) -> 0 | O32: =sumif('SELLING CASH'!E:E,C32,'SELLING CASH'!F:F) -> 3 | P32: =sumif('SELLING CREDIT'!F:F,C32,'SELLING CREDIT'!G:G) -> 0 | Q32: =(N32+G32)-(O32+P32) -> -1 | V32: C-0031 | W32: Bpk. H. Jamil/Butul | X32: =sumif('SELLING CREDIT'!E:E,W32,'SELLING CREDIT'!P:P) -> 0 | Y32: =sumif('PAYMENT CREDIT'!E:E,W32,'PAYMENT CREDIT'!F:F) -> 0 | Z32: =X32-Y32 -> 0
C33: BD 1000 GT | D33: 1000 | E33: GT | F33: BD | G33: 0 | H33: 460000 | I33: 405000 | J33: BIAN | K33: 1 | L33: 0 | M33: Tire | N33: =sumif(PURCHASE!I:I,C33,PURCHASE!J:J) -> 2 | O33: =sumif('SELLING CASH'!E:E,C33,'SELLING CASH'!F:F) -> 0 | P33: =sumif('SELLING CREDIT'!F:F,C33,'SELLING CREDIT'!G:G) -> 2 | Q33: =(N33+G33)-(O33+P33) -> 0 | V33: C-0032 | W33: Bpk. H. Samin/Sudi | X33: =sumif('SELLING CREDIT'!E:E,W33,'SELLING CREDIT'!P:P) -> 0 | Y33: =sumif('PAYMENT CREDIT'!E:E,W33,'PAYMENT CREDIT'!F:F) -> 0 | Z33: =X33-Y33 -> 0
C34: BD 1000*20 | D34: 1000*20 | F34: BD | G34: 0 | H34: 0 | I34: 0 | J34: BIAN | K34: 1 | L34: 0 | M34: Tire | N34: =sumif(PURCHASE!I:I,C34,PURCHASE!J:J) -> 0 | O34: =sumif('SELLING CASH'!E:E,C34,'SELLING CASH'!F:F) -> 0 | P34: =sumif('SELLING CREDIT'!F:F,C34,'SELLING CREDIT'!G:G) -> 2 | Q34: =(N34+G34)-(O34+P34) -> -2 | V34: C-0033 | W34: Bpk. H. Syahro Dangdang | X34: =sumif('SELLING CREDIT'!E:E,W34,'SELLING CREDIT'!P:P) -> 18550000 | Y34: =sumif('PAYMENT CREDIT'!E:E,W34,'PAYMENT CREDIT'!F:F) -> 18550000 | Z34: =X34-Y34 -> 0
C35: BD 12 Aspira | D35: 12 | E35: Aspira | F35: BD | G35: 3 | H35: 100000 | I35: 51000 | J35: BIAN | K35: 1 | L35: 0 | M35: Tire | N35: =sumif(PURCHASE!I:I,C35,PURCHASE!J:J) -> 0 | O35: =sumif('SELLING CASH'!E:E,C35,'SELLING CASH'!F:F) -> 0 | P35: =sumif('SELLING CREDIT'!F:F,C35,'SELLING CREDIT'!G:G) -> 0 | Q35: =(N35+G35)-(O35+P35) -> 3 | V35: C-0034 | W35: Bpk. H. tarlan Cibeureum | X35: =sumif('SELLING CREDIT'!E:E,W35,'SELLING CREDIT'!P:P) -> 3250000 | Y35: =sumif('PAYMENT CREDIT'!E:E,W35,'PAYMENT CREDIT'!F:F) -> 3250000 | Z35: =X35-Y35 -> 0
C36: BD 12 NYB | D36: 12 | E36: NYB | F36: BD | G36: 13 | H36: 100000 | I36: 47000 | J36: BIAN | K36: 1 | L36: 0 | M36: Tire | N36: =sumif(PURCHASE!I:I,C36,PURCHASE!J:J) -> 0 | O36: =sumif('SELLING CASH'!E:E,C36,'SELLING CASH'!F:F) -> 18 | P36: =sumif('SELLING CREDIT'!F:F,C36,'SELLING CREDIT'!G:G) -> 0 | Q36: =(N36+G36)-(O36+P36) -> -5 | V36: C-0035 | W36: Bpk. H. Wido | X36: =sumif('SELLING CREDIT'!E:E,W36,'SELLING CREDIT'!P:P) -> 28610000 | Y36: =sumif('PAYMENT CREDIT'!E:E,W36,'PAYMENT CREDIT'!F:F) -> 33010000 | Z36: =X36-Y36 -> -4400000
C37: BD 13 Aspira | D37: 13 | E37: Aspira | F37: BD | G37: 0 | H37: 90000 | I37: 57000 | J37: BIAN | K37: 1 | L37: 0 | M37: Tire | N37: =sumif(PURCHASE!I:I,C37,PURCHASE!J:J) -> 0 | O37: =sumif('SELLING CASH'!E:E,C37,'SELLING CASH'!F:F) -> 0 | P37: =sumif('SELLING CREDIT'!F:F,C37,'SELLING CREDIT'!G:G) -> 0 | Q37: =(N37+G37)-(O37+P37) -> 0 | V37: C-0036 | W37: Bpk. Hadi Cikitu | X37: =sumif('SELLING CREDIT'!E:E,W37,'SELLING CREDIT'!P:P) -> 19790000 | Y37: =sumif('PAYMENT CREDIT'!E:E,W37,'PAYMENT CREDIT'!F:F) -> 15040000 | Z37: =X37-Y37 -> 4750000
C38: BD 13 Eversave | D38: 13 | E38: Eversave | F38: BD | G38: 0 | H38: 120000 | I38: 72000 | J38: BIAN | K38: 1 | L38: 0 | M38: Tire | N38: =sumif(PURCHASE!I:I,C38,PURCHASE!J:J) -> 0 | O38: =sumif('SELLING CASH'!E:E,C38,'SELLING CASH'!F:F) -> 0 | P38: =sumif('SELLING CREDIT'!F:F,C38,'SELLING CREDIT'!G:G) -> 0 | Q38: =(N38+G38)-(O38+P38) -> 0 | V38: C-0037 | W38: Bpk. Hasyim Pacet | X38: =sumif('SELLING CREDIT'!E:E,W38,'SELLING CREDIT'!P:P) -> 35270000 | Y38: =sumif('PAYMENT CREDIT'!E:E,W38,'PAYMENT CREDIT'!F:F) -> 35270000 | Z38: =X38-Y38 -> 0
C39: BD 13 GT | D39: 13 | E39: GT | F39: BD | G39: 10 | H39: 135000 | I39: 102000 | J39: BIAN | K39: 1 | L39: 0 | M39: Tire | N39: =sumif(PURCHASE!I:I,C39,PURCHASE!J:J) -> 125 | O39: =sumif('SELLING CASH'!E:E,C39,'SELLING CASH'!F:F) -> 122 | P39: =sumif('SELLING CREDIT'!F:F,C39,'SELLING CREDIT'!G:G) -> 2 | Q39: =(N39+G39)-(O39+P39) -> 11 | V39: C-0038 | W39: Bpk. Heri Sapan | X39: =sumif('SELLING CREDIT'!E:E,W39,'SELLING CREDIT'!P:P) -> 0 | Y39: =sumif('PAYMENT CREDIT'!E:E,W39,'PAYMENT CREDIT'!F:F) -> 0 | Z39: =X39-Y39 -> 0
C40: BD 13 IBK | D40: 13 | E40: IBK | F40: BD | G40: 3 | H40: 85000 | I40: 45439.582 | J40: BIAN | K40: 1 | L40: 0 | M40: Tire | N40: =sumif(PURCHASE!I:I,C40,PURCHASE!J:J) -> 255 | O40: =sumif('SELLING CASH'!E:E,C40,'SELLING CASH'!F:F) -> 229 | P40: =sumif('SELLING CREDIT'!F:F,C40,'SELLING CREDIT'!G:G) -> 1 | Q40: =(N40+G40)-(O40+P40) -> 28 | V40: C-0039 | W40: Bpk. Iwan Pajaten | X40: =sumif('SELLING CREDIT'!E:E,W40,'SELLING CREDIT'!P:P) -> 11200000 | Y40: =sumif('PAYMENT CREDIT'!E:E,W40,'PAYMENT CREDIT'!F:F) -> 11200000 | Z40: =X40-Y40 -> 0
...

Sheet EXPENSES
C1: Date | D1: Amount | E1: Explain | F1: Category | G1: Payment | H1: =counta(C:C) -> 1194 | I1: =SUM(D:D) -> 598098018 | K1: Date | L1: Amount | M1: Explain | N1: Category | O1: =sum(L:L) -> 457685000
C2: 45962 | D2: 60000 | E2: Rokok Bian ke Indaramayu | F2: Personal | G2: Cashier | K2: 45965 | L2: 100000 | M2: Admin mah nabil | N2: Store
C3: 45962 | D3: 200000 | E3: Ibu kasih ke PKL | F3: Personal | G3: Cashier | K3: 45965 | L3: 350000 | M3: Ibu bayar ke mamah nabil | N3: Personal
C4: 45962 | D4: 150000 | E4: Biaya service ka ade bian | F4: Personal | G4: Cashier | K4: 45968 | L4: 17000000 | M4: Ka Mah nabil | N4: Store
C5: 45963 | D5: 20000 | E5: Makanan burung | F5: Personal | G5: Cashier | K5: 45972 | L5: 8000000 | M5: Ka Mah nabil | N5: Store
C6: 45963 | D6: 20000 | E6: Tempe | F6: Personal | G6: Cashier | K6: 45976 | L6: 12000000 | M6: Ka Mah nabil | N6: Store
C7: 45964 | D7: 20000 | E7: Bensin Scoopy | F7: Personal | G7: Cashier | K7: 45978 | L7: 20000000 | M7: Ka Mah nabil | N7: Store
C8: 45965 | D8: 20000 | E8: Bian sarapan ciomay | F8: Personal | G8: Cashier | K8: 45979 | L8: 15000000 | M8: Ka Mah nabil | N8: Store
C9: 45965 | D9: 100000 | E9: Bian bensin | F9: Personal | G9: Cashier | K9: 45980 | L9: 10000000 | M9: Ka Mah nabil | N9: Store
C10: 45965 | D10: 15000 | E10: Cat rambut bian | F10: Personal | G10: Cashier | K10: 45981 | L10: 100000 | M10: Ka Mah nabil | N10: Store
C11: 45965 | D11: 20000 | E11: Kosentra/makanan ayam | F11: Personal | G11: Cashier | K11: 45981 | L11: 10000000 | M11: Ka Mah nabil | N11: Store
C12: 45965 | D12: 15000 | E12: nasi goreng bian | F12: Personal | G12: Cashier | K12: 45982 | L12: 20000000 | M12: Ka Mah nabil | N12: Store
C13: 45965 | D13: 32000 | E13: Shopeefood Bian | F13: Personal | G13: Cashier | K13: 45985 | L13: 10100000 | M13: Ka Mah nabil | N13: Store
C14: 45965 | D14: 350000 | E14: Paket yang mah angel | F14: Personal | G14: IBU | K14: 45986 | L14: 10100000 | M14: Ka Mah nabil | N14: Store
C15: 45965 | D15: 2500000 | E15: PAKET UANG ke mah nabil | F15: Personal | G15: IBU | H15: Link | K15: 45986 | L15: 7100000 | M15: Ka Mah nabil | N15: Store
C16: 45965 | D16: 700000 | E16: Shopee Ibu | F16: Personal | G16: IBU | K16: 45988 | L16: 3000000 | M16: Ka Mah nabil | N16: Store
C17: 45966 | D17: 13000 | E17: Bian sarapan ciomay | F17: Personal | G17: Cashier | K17: 45994 | L17: 10100000 | M17: Ka Mah nabil | N17: Store
C18: 45966 | D18: 50000 | E18: WD 1 | F18: Store | G18: Cashier | K18: 45995 | L18: 11000000 | M18: Ka Mah nabil | N18: Store
C19: 45966 | D19: 81000 | E19: BIAN COD | F19: Personal | G19: Cashier | K19: 45996 | L19: 15150000 | M19: Ka Mah nabil | N19: Store
